Workbook

Sheet DB
A1: Visited by | B1: Date Visit | C1: Code | D1: Site name | E1: Locality | F1: COORDINATES | G1: Power Check | H1: Connectivity Check | I1: Hardware Check | J1: Cables Check | K1: Remarks
A2: EBANOG | B2: 46168 | C2: L4-003-04D4A | D2: M. B. Asistio Sr. High School Unit | E2: Caloocan City | F2: 14.650111, 120.965174 | G2: Yes | H2: No | I2: Yes | J2: Yes | K2: Blinking LOS
A3: EBANOG | B3: 46125 | C3: L4-003-04A0B | D3: Kasarinlan High School | E3: Caloocan City
A4: EBANOG | B4: 46125 | C4: L4-003-05F88 | D4: Barangay 12 Health Center | E4: Caloocan City | F4: 14.6517266, 120.9640138
A5: EBANOG | B5: 46175 | C5: L4-003-04D56 | D5: Manuel L. Quezon High School | E5: Caloocan City | F5: 14.769255, 121.077191 | G5: Yes | H5: Yes | I5: Yes | J5: Yes | K5: Online no splash page
A6: EBANOG | B6: 46127 | C6: L4-003-04D5C | D6: Sampaguita High School | E6: Caloocan City
A7: EBANOG | B7: 46182 | C7: L4-003-05893 | D7: University of Caloocan City - Camarin Business Campus | E7: Caloocan City | F7: 14.761965, 121.050172 | G7: Yes | H7: Yes | I7: Yes | J7: Yes | K7: Reset modem
A8: EBANOG | B8: 46133 | C8: L4-003-04D5D | D8: Bagumbong High School | E8: Caloocan City | F8: 14.7476037, 121.0275501
A9: EBANOG | B9: 46168 | C9: L4-003-04D51 | D9: Caybiga High School | E9: Caloocan City | F9: 14.724718, 121.005159 | G9: Yes | H9: Yes | I9: Yes | J9: Yes | K9: Reset modem
A10: EBANOG | B10: 46135 | C10: L4-003-04D52 | D10: Baesa High School | E10: Caloocan City
A11: EBANOG | B11: 46176 | C11: L4-003-063CE | D11: Barangay 14 Health Center | E11: Caloocan City | F11: 14.6485132, 120.9647162 | K11: Defective modem and AP
A12: EBANOG | B12: 46176 | C12: L4-003-05F92 | D12: Sampalukan Health Center | E12: Caloocan City | F12: 14.643506, 120.973190 | G12: Yes | H12: Yes | I12: Yes | J12: Yes | K12: Reset Modem
A13: EBANOG | B13: 46139 | C13: L4-003-0079C | D13: Tandang Sora Integrated School | E13: Caloocan City
A14: POGI | B14: 45309 | C14: L4-003-04929 | D14: Kalayaan National High School | E14: Caloocan City
A15: POGI | B15: 46060 | C15: L4-003-04D59 | D15: Amparo High School | E15: Caloocan City
A16: EBANOG | B16: 46155 | C16: L4-003-0078B | D16: San Jose Elementary School - Annex | E16: Caloocan City | F16: 14.639301, 120.989119 | G16: Yes | H16: Yes | I16: Yes | J16: Yes | K16: Reset modem (Oneaccess)
A17: EBANOG | B17: 46147 | C17: L4-003-007D8 | D17: Sta. Quiteria Elementary School | E17: Caloocan City | F17: 14.680657, 121.009711 | G17: Yes | H17: Yes | I17: Yes | J17: Yes | K17: Reset modem
A18: EBANOG | B18: 46147 | C18: L4-003-04D4F | D18: Llano High School | E18: Caloocan City | F18: 14.732024, 121.010752 | G18: Yes | H18: No | I18: Yes | J18: Yes | K18: Blinking LOS/SSID present (2)/Lan 2 With activity
A19: EBANOG | B19: 46155 | C19: L4-003-04A10 | D19: CHS - Cielito Zamora - Annex 2 | E19: Caloocan City | F19: 14.746583, 121.050172 | G19: Yes | H19: No | I19: Yes | J19: Yes | K19: Blinking LOS
A20: EBANOG | B20: 46163 | C20: L4-003-0017F | D20: Pres. Diosdado Macapagal Memorial Medical Center | E20: Caloocan City | F20: 14.647097, 120.972037 | G20: No | H20: No | I20: Yes | J20: Yes | K20: Defective commbox breaker
A21: EBANOG | B21: 46118 | C21: L4-011-0006B | D21: Land Registration Authority | E21: IGOV
A22: EBANOG | B22: 46118 | C22: L4-011-0665B | D22: Bureau of Fire Protection | E22: IGOV
A23: EBANOG | B23: 46119 | C23: L4-011-00006 | D23: Office of the Ombudsman | E23: IGOV
A24: EBANOG | B24: 46119 | C24: L4-011-0008B | D24: Bureau of Jail Management and Penology | E24: IGOV
A25: EBANOG | B25: 46142 | C25: L4-011-00052 | D25: National Power Corporation | E25: IGOV
A26: POGI | B26: 43831 | C26: L4-011-00047 | D26: Philippine Atmospheric, Geophysical and Astronomical Services Administration | E26: IGOV
A27: AZIMUTH_ADMIN | B27: 46023 | C27: L4-022-00009 | D27: Department of Science and Technology | E27: IGOV
A28: EBANOG | B28: 45780 | C28: L4-005-00016 | D28: Bureau of the Treasury | E28: IGOV | F28: 14.744307, 120.972969 | G28: Yes | H28: Yes | I28: Yes | J28: Yes | K28: No internet
A29: EBANOG | B29: 45780 | C29: L4-008-00010 | D29: Board of Investments | E29: IGOV | F29: 14.74449260, 120.97239530
A30: ADMIN | C30: L4-005-0008F | D30: Bureau of Customs | E30: IGOV | F30: 14.744307, 120.972969 | G30: Yes | H30: No | I30: Yes | J30: Yes | K30: Blinking LOS
A31: ADMIN | C31: L4-005-00045 | D31: Philippine Coast Guard | E31: IGOV | F31: 14.744307, 120.972969 | G31: Yes | H31: Yes | I31: Yes | J31: Yes
A32: EBANOG | B32: 45781 | C32: L4-005-0006E | D32: Insurance Commission | E32: IGOV | F32: 14.744316, 120.972915
A33: EBANOG | B33: 46126 | C33: L4-004-0068C | D33: Almanza Elementary School - T. S. Cruz Annex | E33: Las Piñas City | F33: 14.4187517, 121.0177683
A34: EBANOG | B34: 46126 | C34: L4-004-049F2 | D34: Las Piñas East National High School - Equitable Annex | E34: Las Piñas City | F34: 14.4330711, 121.0018142
A35: EBANOG | B35: 46134 | C35: L4-004-0069E | D35: CAA Elementary School - Annex | E35: Las Piñas City
A36: EBANOG | B36: 46170 | C36: L4-004-0069B | D36: Pamplona Elementary School - Central | E36: Las Piñas City | F36: 14.458122, 120.970192 | G36: Yes | H36: Yes | I36: Yes | J36: Yes | K36: Reset modem
A37: EBANOG | B37: 46134 | C37: L4-004-05E9A | D37: Pulanglupa Uno Health Center | E37: Las Piñas City
A38: EBANOG | B38: 46150 | C38: L4-004-04D24 | D38: Las Piñas National High School | E38: Las Piñas City | F38: 14.482470, 120.981228 | G38: Yes | H38: No | I38: Yes | J38: Yes | K38: Blinking LOS
A39: EBANOG | B39: 46150 | C39: L4-004-05E91 | D39: Manuyo Uno Health Center | E39: Las Piñas City | K39: site is under construction
A40: POGI | B40: 46147 | C40: L4-004-049EE | D40: T. S. Cruz High School | E40: Las Piñas City
...

Sheet UsersDB
A1: username | B1: password
A2: EBANOG | B2: admin
A3: admin | B3: admin
A4: POGI | B4: pogi123
A5: AZIMUTH_ADMIN | B5: admin

Sheet MAIN
A1: EBANOG | D1: Other income | E1: Date | F1: =IFERROR(__xludf.DUMMYFUNCTION("LET( data, QUERY( FILTER(DB!A:D, DB!A:A=A1, DB!B:B>=A2, DB!B:B<=B2), ""select Col2, Col3, Col4 order by Col2 asc"", 0 ), { {""NO."",""DATE"",""CODE"",""SITE NAME""}; {SEQUENCE(ROWS(data)), data} } ) "),"NO.") -> NO. | G1: =IFERROR(__xludf.DUMMYFUNCTION("""COMPUTED_VALUE"""),"DATE") -> DATE | H1: =IFERROR(__xludf.DUMMYFUNCTION("""COMPUTED_VALUE"""),"CODE") -> CODE | I1: =IFERROR(__xludf.DUMMYFUNCTION("""COMPUTED_VALUE"""),"SITE NAME") -> SITE NAME
A2: 46174 | B2: 46188 | C2: =TODAY()-30 -> 46154 | E2: =A2 -> 46174 | F2: =IFERROR(__xludf.DUMMYFUNCTION("""COMPUTED_VALUE"""),1.0) -> 1 | G2: =IFERROR(__xludf.DUMMYFUNCTION("""COMPUTED_VALUE"""),46174.0) -> 46174 | H2: =IFERROR(__xludf.DUMMYFUNCTION("""COMPUTED_VALUE"""),"L4-012-05FCF") -> L4-012-05FCF | I2: =IFERROR(__xludf.DUMMYFUNCTION("""COMPUTED_VALUE"""),"Mapulang Lupa Health Center") -> Mapulang Lupa Health Center
A3: LOCALITY | B3: No. of Sites | C3: TODAY | D3: 879 | E3: =E2+1 -> 46175 | F3: =IFERROR(__xludf.DUMMYFUNCTION("""COMPUTED_VALUE"""),2.0) -> 2 | G3: =IFERROR(__xludf.DUMMYFUNCTION("""COMPUTED_VALUE"""),46174.0) -> 46174 | H3: =IFERROR(__xludf.DUMMYFUNCTION("""COMPUTED_VALUE"""),"L4-012-04D19") -> L4-012-04D19 | I3: =IFERROR(__xludf.DUMMYFUNCTION("""COMPUTED_VALUE"""),"Valenzuela National High School ") -> Valenzuela National High School
A4: IGOV | B4: =COUNTIFS(DB!E:E,A4,DB!B:B,">="&$A$2,DB!B:B,"<="&$B$2,DB!A:A,"="&$A$1) -> 0 | C4: =COUNTIFS(DB!A:A,"="&$A$1,DB!B:B,TODAY()) -> 2 | D4: =109+407 -> 516 | E4: =E3+1 -> 46176 | F4: =IFERROR(__xludf.DUMMYFUNCTION("""COMPUTED_VALUE"""),3.0) -> 3 | G4: =IFERROR(__xludf.DUMMYFUNCTION("""COMPUTED_VALUE"""),46175.0) -> 46175 | H4: =IFERROR(__xludf.DUMMYFUNCTION("""COMPUTED_VALUE"""),"L4-003-04D56") -> L4-003-04D56 | I4: =IFERROR(__xludf.DUMMYFUNCTION("""COMPUTED_VALUE"""),"Manuel L. Quezon High School") -> Manuel L. Quezon High School
A5: Caloocan City | B5: =COUNTIFS(DB!E:E,A5,DB!B:B,">="&$A$2,DB!B:B,"<="&$B$2,DB!A:A,"="&$A$1) -> 7 | D5: =265+438 -> 703 | E5: =E4+1 -> 46177 | F5: =IFERROR(__xludf.DUMMYFUNCTION("""COMPUTED_VALUE"""),4.0) -> 4 | G5: =IFERROR(__xludf.DUMMYFUNCTION("""COMPUTED_VALUE"""),46175.0) -> 46175 | H5: =IFERROR(__xludf.DUMMYFUNCTION("""COMPUTED_VALUE"""),"L4-003-063C4") -> L4-003-063C4 | I5: =IFERROR(__xludf.DUMMYFUNCTION("""COMPUTED_VALUE"""),"178-A Health Center ") -> 178-A Health Center
A6: Malabon City | B6: =COUNTIFS(DB!E:E,A6,DB!B:B,">="&$A$2,DB!B:B,"<="&$B$2,DB!A:A,"="&$A$1) -> 1 | C6: AVG INCOME | D6: =134+413 -> 547 | E6: =E5+1 -> 46178 | F6: =IFERROR(__xludf.DUMMYFUNCTION("""COMPUTED_VALUE"""),5.0) -> 5 | G6: =IFERROR(__xludf.DUMMYFUNCTION("""COMPUTED_VALUE"""),46176.0) -> 46176 | H6: =IFERROR(__xludf.DUMMYFUNCTION("""COMPUTED_VALUE"""),"L4-003-063CE") -> L4-003-063CE | I6: =IFERROR(__xludf.DUMMYFUNCTION("""COMPUTED_VALUE"""),"Barangay 14 Health Center") -> Barangay 14 Health Center
A7: Navotas City | B7: =COUNTIFS(DB!E:E,A7,DB!B:B,">="&$A$2,DB!B:B,"<="&$B$2,DB!A:A,"="&$A$1) -> 1 | C7: =B49 -> 842.84615 | D7: =460+511 -> 971 | E7: =E6+1 -> 46179 | F7: =IFERROR(__xludf.DUMMYFUNCTION("""COMPUTED_VALUE"""),6.0) -> 6 | G7: =IFERROR(__xludf.DUMMYFUNCTION("""COMPUTED_VALUE"""),46176.0) -> 46176 | H7: =IFERROR(__xludf.DUMMYFUNCTION("""COMPUTED_VALUE"""),"L4-003-05F92") -> L4-003-05F92 | I7: =IFERROR(__xludf.DUMMYFUNCTION("""COMPUTED_VALUE"""),"Sampalukan Health Center") -> Sampalukan Health Center
A8: Valenzuela City | B8: =COUNTIFS(DB!E:E,A8,DB!B:B,">="&$A$2,DB!B:B,"<="&$B$2,DB!A:A,"="&$A$1) -> 5 | C8: 13 | D8: 19 | E8: =E7+1 -> 46180 | F8: =IFERROR(__xludf.DUMMYFUNCTION("""COMPUTED_VALUE"""),7.0) -> 7 | G8: =IFERROR(__xludf.DUMMYFUNCTION("""COMPUTED_VALUE"""),46176.0) -> 46176 | H8: =IFERROR(__xludf.DUMMYFUNCTION("""COMPUTED_VALUE"""),"L4-003-00795") -> L4-003-00795 | I8: =IFERROR(__xludf.DUMMYFUNCTION("""COMPUTED_VALUE"""),"Grace Park Elementary School - Main ") -> Grace Park Elementary School - Main
A9: Quezon City | B9: =COUNTIFS(DB!E:E,A9,DB!B:B,">="&$A$2,DB!B:B,"<="&$B$2,DB!A:A,"="&$A$1) -> 3 | C9: =C7*C8 -> 10957 | D9: 220 | E9: =E8+1 -> 46181 | F9: =IFERROR(__xludf.DUMMYFUNCTION("""COMPUTED_VALUE"""),8.0) -> 8 | G9: =IFERROR(__xludf.DUMMYFUNCTION("""COMPUTED_VALUE"""),46176.0) -> 46176 | H9: =IFERROR(__xludf.DUMMYFUNCTION("""COMPUTED_VALUE"""),"L4-003-05F87") -> L4-003-05F87 | I9: =IFERROR(__xludf.DUMMYFUNCTION("""COMPUTED_VALUE"""),"Barangay 18 Health Center") -> Barangay 18 Health Center
A10: Manila City | B10: =COUNTIFS(DB!E:E,A10,DB!B:B,">="&$A$2,DB!B:B,"<="&$B$2,DB!A:A,"="&$A$1) -> 1 | C10: =SUM(D2:D17,B23) -> 10957 | D10: 358 | E10: =E9+1 -> 46182 | F10: =IFERROR(__xludf.DUMMYFUNCTION("""COMPUTED_VALUE"""),9.0) -> 9 | G10: =IFERROR(__xludf.DUMMYFUNCTION("""COMPUTED_VALUE"""),46177.0) -> 46177 | H10: =IFERROR(__xludf.DUMMYFUNCTION("""COMPUTED_VALUE"""),"L4-013-05EC1") -> L4-013-05EC1 | I10: =IFERROR(__xludf.DUMMYFUNCTION("""COMPUTED_VALUE"""),"Don Bosco Health Center ") -> Don Bosco Health Center
A11: Pasay City | B11: =COUNTIFS(DB!E:E,A11,DB!B:B,">="&$A$2,DB!B:B,"<="&$B$2,DB!A:A,"="&$A$1) -> 0 | D11: =386+19 -> 405 | E11: =E10+1 -> 46183 | F11: =IFERROR(__xludf.DUMMYFUNCTION("""COMPUTED_VALUE"""),10.0) -> 10 | G11: =IFERROR(__xludf.DUMMYFUNCTION("""COMPUTED_VALUE"""),46177.0) -> 46177 | H11: =IFERROR(__xludf.DUMMYFUNCTION("""COMPUTED_VALUE"""),"L4-004-05E99") -> L4-004-05E99 | I11: =IFERROR(__xludf.DUMMYFUNCTION("""COMPUTED_VALUE"""),"Pulanglupa Dos Health Center") -> Pulanglupa Dos Health Center
A12: Parañaque City | B12: =COUNTIFS(DB!E:E,A12,DB!B:B,">="&$A$2,DB!B:B,"<="&$B$2,DB!A:A,"="&$A$1) -> 1 | D12: 839 | E12: =E11+1 -> 46184 | F12: =IFERROR(__xludf.DUMMYFUNCTION("""COMPUTED_VALUE"""),11.0) -> 11 | G12: =IFERROR(__xludf.DUMMYFUNCTION("""COMPUTED_VALUE"""),46181.0) -> 46181 | H12: =IFERROR(__xludf.DUMMYFUNCTION("""COMPUTED_VALUE"""),"L4-007-049E0") -> L4-007-049E0 | I12: =IFERROR(__xludf.DUMMYFUNCTION("""COMPUTED_VALUE"""),"Tañong Integrated School") -> Tañong Integrated School
A13: Taguig City | B13: =COUNTIFS(DB!E:E,A13,DB!B:B,">="&$A$2,DB!B:B,"<="&$B$2,DB!A:A,"="&$A$1) -> 0 | E13: =E12+1 -> 46185 | F13: =IFERROR(__xludf.DUMMYFUNCTION("""COMPUTED_VALUE"""),12.0) -> 12 | G13: =IFERROR(__xludf.DUMMYFUNCTION("""COMPUTED_VALUE"""),46181.0) -> 46181 | H13: =IFERROR(__xludf.DUMMYFUNCTION("""COMPUTED_VALUE"""),"L4-012-007FF") -> L4-012-007FF | I13: =IFERROR(__xludf.DUMMYFUNCTION("""COMPUTED_VALUE"""),"Punturin Elementary School") -> Punturin Elementary School
A14: Pasig City | B14: =COUNTIFS(DB!E:E,A14,DB!B:B,">="&$A$2,DB!B:B,"<="&$B$2,DB!A:A,"="&$A$1) -> 0 | E14: =E13+1 -> 46186 | F14: =IFERROR(__xludf.DUMMYFUNCTION("""COMPUTED_VALUE"""),13.0) -> 13 | G14: =IFERROR(__xludf.DUMMYFUNCTION("""COMPUTED_VALUE"""),46181.0) -> 46181 | H14: =IFERROR(__xludf.DUMMYFUNCTION("""COMPUTED_VALUE"""),"L4-012-007F4") -> L4-012-007F4 | I14: =IFERROR(__xludf.DUMMYFUNCTION("""COMPUTED_VALUE"""),"Canumay East Elementary School") -> Canumay East Elementary School
A15: Marikina City | B15: =COUNTIFS(DB!E:E,A15,DB!B:B,">="&$A$2,DB!B:B,"<="&$B$2,DB!A:A,"="&$A$1) -> 0 | E15: =E14+1 -> 46187 | F15: =IFERROR(__xludf.DUMMYFUNCTION("""COMPUTED_VALUE"""),14.0) -> 14 | G15: =IFERROR(__xludf.DUMMYFUNCTION("""COMPUTED_VALUE"""),46181.0) -> 46181 | H15: =IFERROR(__xludf.DUMMYFUNCTION("""COMPUTED_VALUE"""),"L4-012-05FE0") -> L4-012-05FE0 | I15: =IFERROR(__xludf.DUMMYFUNCTION("""COMPUTED_VALUE"""),"Tugatog Health Center") -> Tugatog Health Center
A16: Makati City | B16: =COUNTIFS(DB!E:E,A16,DB!B:B,">="&$A$2,DB!B:B,"<="&$B$2,DB!A:A,"="&$A$1) -> 0 | E16: =E15+1 -> 46188 | F16: =IFERROR(__xludf.DUMMYFUNCTION("""COMPUTED_VALUE"""),15.0) -> 15 | G16: =IFERROR(__xludf.DUMMYFUNCTION("""COMPUTED_VALUE"""),46181.0) -> 46181 | H16: =IFERROR(__xludf.DUMMYFUNCTION("""COMPUTED_VALUE"""),"L4-00A-05FAC") -> L4-00A-05FAC | I16: =IFERROR(__xludf.DUMMYFUNCTION("""COMPUTED_VALUE"""),"Bagumbayan Health Center") -> Bagumbayan Health Center
A17: Las Piñas City | B17: =COUNTIFS(DB!E:E,A17,DB!B:B,">="&$A$2,DB!B:B,"<="&$B$2,DB!A:A,"="&$A$1) -> 1 | E17: =E16+1 -> 46189 | F17: =IFERROR(__xludf.DUMMYFUNCTION("""COMPUTED_VALUE"""),16.0) -> 16 | G17: =IFERROR(__xludf.DUMMYFUNCTION("""COMPUTED_VALUE"""),46182.0) -> 46182 | H17: =IFERROR(__xludf.DUMMYFUNCTION("""COMPUTED_VALUE"""),"L4-003-05893") -> L4-003-05893 | I17: =IFERROR(__xludf.DUMMYFUNCTION("""COMPUTED_VALUE"""),"University of Caloocan City - Camarin Business Campus") -> University of Caloocan City - Camarin Business Campus
A18: Muntinlupa City | B18: =COUNTIFS(DB!E:E,A18,DB!B:B,">="&$A$2,DB!B:B,"<="&$B$2,DB!A:A,"="&$A$1) -> 2 | D18: =SUM(D2:D17) -> 5457 | F18: =IFERROR(__xludf.DUMMYFUNCTION("""COMPUTED_VALUE"""),17.0) -> 17 | G18: =IFERROR(__xludf.DUMMYFUNCTION("""COMPUTED_VALUE"""),46182.0) -> 46182 | H18: =IFERROR(__xludf.DUMMYFUNCTION("""COMPUTED_VALUE"""),"L4-011-00643") -> L4-011-00643 | I18: =IFERROR(__xludf.DUMMYFUNCTION("""COMPUTED_VALUE"""),"San Jose Elementary School - Pag-Ibig sa Nayon Annex") -> San Jose Elementary School - Pag-Ibig sa Nayon Annex
A19: Mandaluyong City | B19: =COUNTIFS(DB!E:E,A19,DB!B:B,">="&$A$2,DB!B:B,"<="&$B$2,DB!A:A,"="&$A$1) -> 0 | F19: =IFERROR(__xludf.DUMMYFUNCTION("""COMPUTED_VALUE"""),18.0) -> 18 | G19: =IFERROR(__xludf.DUMMYFUNCTION("""COMPUTED_VALUE"""),46182.0) -> 46182 | H19: =IFERROR(__xludf.DUMMYFUNCTION("""COMPUTED_VALUE"""),"L4-011-00644") -> L4-011-00644 | I19: =IFERROR(__xludf.DUMMYFUNCTION("""COMPUTED_VALUE"""),"Sinag-Tala Elementary School ") -> Sinag-Tala Elementary School
A20: San Juan City | B20: =COUNTIFS(DB!E:E,A20,DB!B:B,">="&$A$2,DB!B:B,"<="&$B$2,DB!A:A,"="&$A$1) -> 0 | F20: =IFERROR(__xludf.DUMMYFUNCTION("""COMPUTED_VALUE"""),19.0) -> 19 | G20: =IFERROR(__xludf.DUMMYFUNCTION("""COMPUTED_VALUE"""),46183.0) -> 46183 | H20: =IFERROR(__xludf.DUMMYFUNCTION("""COMPUTED_VALUE"""),"L4-00B-00686") -> L4-00B-00686 | I20: =IFERROR(__xludf.DUMMYFUNCTION("""COMPUTED_VALUE"""),"Soldiers' Hills Elementary School") -> Soldiers' Hills Elementary School
A21: Total Site | B21: =SUM(B4:B20) -> 22 | F21: =IFERROR(__xludf.DUMMYFUNCTION("""COMPUTED_VALUE"""),20.0) -> 20 | G21: =IFERROR(__xludf.DUMMYFUNCTION("""COMPUTED_VALUE"""),46183.0) -> 46183 | H21: =IFERROR(__xludf.DUMMYFUNCTION("""COMPUTED_VALUE"""),"L4-00B-04CFF") -> L4-00B-04CFF | I21: =IFERROR(__xludf.DUMMYFUNCTION("""COMPUTED_VALUE"""),"Muntinlupa National High School") -> Muntinlupa National High School
F22: =IFERROR(__xludf.DUMMYFUNCTION("""COMPUTED_VALUE"""),21.0) -> 21 | G22: =IFERROR(__xludf.DUMMYFUNCTION("""COMPUTED_VALUE"""),46184.0) -> 46184 | H22: =IFERROR(__xludf.DUMMYFUNCTION("""COMPUTED_VALUE"""),"L4-011-00626") -> L4-011-00626 | I22: =IFERROR(__xludf.DUMMYFUNCTION("""COMPUTED_VALUE""")," Libis Elementary School") -> Libis Elementary School
A23: Total Income | B23: =250*B21 -> 5500 | F23: =IFERROR(__xludf.DUMMYFUNCTION("""COMPUTED_VALUE"""),22.0) -> 22 | G23: =IFERROR(__xludf.DUMMYFUNCTION("""COMPUTED_VALUE"""),46184.0) -> 46184 | H23: =IFERROR(__xludf.DUMMYFUNCTION("""COMPUTED_VALUE"""),"L4-005-05E7A") -> L4-005-05E7A | I23: =IFERROR(__xludf.DUMMYFUNCTION("""COMPUTED_VALUE"""),"San Miguel Health Center") -> San Miguel Health Center
A24: LESS CA | B24: 2500
A25: MOTOR | B25: 1000
A26: NET INCOME | B26: =B23-B24-B25 -> 2000
A29: =IFERROR(__xludf.DUMMYFUNCTION("{ QUERY( FILTER(DB!A:C, DB!A:A=A1, DB!B:B>=A2, DB!B:B<=B2), ""select Col2, count(Col2) group by Col2 label Col2 'DATE', count(Col2) 'Supported Sites'"", 0 ); {""TOTAL"", SUM( QUERY( FILTER(DB!A:C, DB!A:A=A1, DB"&"!B:B>=A2, DB!B:B<=B2), ""select count(Col2) group by Col2"", 0 ) ) } }"),"DATE") -> DATE | B29: =IFERROR(__xludf.DUMMYFUNCTION("""COMPUTED_VALUE"""),"Supported Sites") -> Supported Sites
A30: =IFERROR(__xludf.DUMMYFUNCTION("""COMPUTED_VALUE"""),46174.0) -> 46174 | B30: =IFERROR(__xludf.DUMMYFUNCTION("""COMPUTED_VALUE"""),2.0) -> 2
A31: =IFERROR(__xludf.DUMMYFUNCTION("""COMPUTED_VALUE"""),46175.0) -> 46175 | B31: =IFERROR(__xludf.DUMMYFUNCTION("""COMPUTED_VALUE"""),2.0) -> 2
A32: =IFERROR(__xludf.DUMMYFUNCTION("""COMPUTED_VALUE"""),46176.0) -> 46176 | B32: =IFERROR(__xludf.DUMMYFUNCTION("""COMPUTED_VALUE"""),4.0) -> 4
A33: =IFERROR(__xludf.DUMMYFUNCTION("""COMPUTED_VALUE"""),46177.0) -> 46177 | B33: =IFERROR(__xludf.DUMMYFUNCTION("""COMPUTED_VALUE"""),2.0) -> 2
A34: =IFERROR(__xludf.DUMMYFUNCTION("""COMPUTED_VALUE"""),46181.0) -> 46181 | B34: =IFERROR(__xludf.DUMMYFUNCTION("""COMPUTED_VALUE"""),5.0) -> 5
A35: =IFERROR(__xludf.DUMMYFUNCTION("""COMPUTED_VALUE"""),46182.0) -> 46182 | B35: =IFERROR(__xludf.DUMMYFUNCTION("""COMPUTED_VALUE"""),3.0) -> 3
A36: =IFERROR(__xludf.DUMMYFUNCTION("""COMPUTED_VALUE"""),46183.0) -> 46183 | B36: =IFERROR(__xludf.DUMMYFUNCTION("""COMPUTED_VALUE"""),2.0) -> 2
A37: =IFERROR(__xludf.DUMMYFUNCTION("""COMPUTED_VALUE"""),46184.0) -> 46184 | B37: =IFERROR(__xludf.DUMMYFUNCTION("""COMPUTED_VALUE"""),2.0) -> 2
A38: =IFERROR(__xludf.DUMMYFUNCTION("""COMPUTED_VALUE"""),"TOTAL") -> TOTAL | B38: =IFERROR(__xludf.DUMMYFUNCTION("""COMPUTED_VALUE"""),22.0) -> 22
A41: Gas Allowance | B41: =COUNT(A30:A40)*100 -> 800
A43: CA | B43: =B24 -> 2500
A44: Motor(3) | B44: =B25 -> 1000
A46: ERWIN ANOG
...

Sheet Master
A1: Date | B1: RAW | C1: INPUT
A2: 46181 | B2: =COUNTIF(A5:A972,"*L4*" ) -> 29 | C2: =SUM(MALABON!B1,MANILA!B1,CALOOCAN!B1,VALENZUELA!B1,'QUEZON CITY'!B1,'LAS PINAS'!B1,TAGUIG!B1,NAVOTAS!B1,Paranaque!B1,Pasay!B1,Marikina!B1,MAKATI!B1,'SAN JUAN'!B1,MUNTINLUPA!B1,PASIG!B1,MANDALUYONG!B1) -> 29
A4: Location ID | B4: SITE NAME | C4: LAST DATE VISIT
A5: Caloocan City
A6: L4-003-063CE | B6: Barangay 14 Health Center | C6: {=XLOOKUP(A6,DB!C:C,DB!B:B,"")} -> 46176
A7: L4-003-007B8 | B7: Bagong Barrio Elementary School | C7: {=XLOOKUP(A7,DB!C:C,DB!B:B,"")}
A8: L4-003-0017F | B8: Pres. Diosdado Macapagal Memorial Medical Center | C8: {=XLOOKUP(A8,DB!C:C,DB!B:B,"")} -> 46163
A9: L4-003-05893 | B9: University of Caloocan City - Camarin Business Campus | C9: {=XLOOKUP(A9,DB!C:C,DB!B:B,"")} -> 46182
C10: {=XLOOKUP(A10,DB!C:C,DB!B:B,"")}
A11: Makati City | C11: {=XLOOKUP(A11,DB!C:C,DB!B:B,"")}
A12: L4-008-00010 | B12: Board of Investments | C12: {=XLOOKUP(A12,DB!C:C,DB!B:B,"")} -> 45780
A13: L4-008-006F2 | B13: Hen. Pio del Pilar Elementary School I | C13: {=XLOOKUP(A13,DB!C:C,DB!B:B,"")}
A14: L4-008-00701 | B14: Makati Elementary School | C14: {=XLOOKUP(A14,DB!C:C,DB!B:B,"")}
C15: {=XLOOKUP(A15,DB!C:C,DB!B:B,"")}
A16: Malabon City | C16: {=XLOOKUP(A16,DB!C:C,DB!B:B,"")}
A17: L4-007-049E0 | B17: Tañong Integrated School | C17: {=XLOOKUP(A17,DB!C:C,DB!B:B,"")} -> 46181
C18: {=XLOOKUP(A18,DB!C:C,DB!B:B,"")}
A19: Manila City | C19: {=XLOOKUP(A19,DB!C:C,DB!B:B,"")}
A20: L4-005-05E5A | B20: M. Earnshaw Health Center | C20: {=XLOOKUP(A20,DB!C:C,DB!B:B,"")} -> 46135
A21: L4-005-0007D | B21: Department of Finance | C21: {=XLOOKUP(A21,DB!C:C,DB!B:B,"")}
A22: L4-005-0008F | B22: Bureau of Customs | C22: {=XLOOKUP(A22,DB!C:C,DB!B:B,"")}
A23: L4-005-05E7A | B23: San Miguel Health Center | C23: {=XLOOKUP(A23,DB!C:C,DB!B:B,"")} -> 46184
A24: L4-005-00718 | B24: E. delos Santos Elementary School | C24: {=XLOOKUP(A24,DB!C:C,DB!B:B,"")}
A25: L4-005-0006D | B25: Intramuros Administration | C25: {=XLOOKUP(A25,DB!C:C,DB!B:B,"")}
C26: {=XLOOKUP(A26,DB!C:C,DB!B:B,"")}
A27: Muntinlupa City | C27: {=XLOOKUP(A27,DB!C:C,DB!B:B,"")}
A28: L4-00B-04CFF | B28: Muntinlupa National High School | C28: {=XLOOKUP(A28,DB!C:C,DB!B:B,"")} -> 46183
A29: L4-00B-00686 | B29: Soldiers' Hills Elementary School | C29: {=XLOOKUP(A29,DB!C:C,DB!B:B,"")} -> 46183
C30: {=XLOOKUP(A30,DB!C:C,DB!B:B,"")}
A31: Navotas City | C31: {=XLOOKUP(A31,DB!C:C,DB!B:B,"")}
A32: L4-00A-05FAC | B32: Bagumbayan Health Center | C32: {=XLOOKUP(A32,DB!C:C,DB!B:B,"")} -> 46181
C33: {=XLOOKUP(A33,DB!C:C,DB!B:B,"")}
A34: Parañaque City | C34: {=XLOOKUP(A34,DB!C:C,DB!B:B,"")}
A35: L4-013-05ED0 | B35: Vitalez Health Center | C35: {=XLOOKUP(A35,DB!C:C,DB!B:B,"")}
C36: {=XLOOKUP(A36,DB!C:C,DB!B:B,"")}
A37: Pasay City | C37: {=XLOOKUP(A37,DB!C:C,DB!B:B,"")}
A38: L4-008-06395 | B38: Philippine National Police Aviation Security Group | C38: {=XLOOKUP(A38,DB!C:C,DB!B:B,"")}
A39: L4-015-0004B | B39: Overseas Workers Welfare Administration | C39: {=XLOOKUP(A39,DB!C:C,DB!B:B,"")}
C40: {=XLOOKUP(A40,DB!C:C,DB!B:B,"")}
A41: Quezon City | C41: {=XLOOKUP(A41,DB!C:C,DB!B:B,"")}
...

Sheet MANILA
A1: TOTAL | B1: =COUNTIF(A3:A1001,"*L4*") -> 7 | D1: =MAIN!C2 -> 46154
A2: Code | B2: SITE | C2: Status | D2: Date visited | E2: Coordinates
A3: =IFERROR(__xludf.DUMMYFUNCTION("QUERY(Master!A2:B1001, ""SELECT A, B WHERE A STARTS WITH 'L4-005'"", 0)"),"L4-005-05E5A") -> L4-005-05E5A | B3: =IFERROR(__xludf.DUMMYFUNCTION("""COMPUTED_VALUE"""),"M. Earnshaw Health Center") -> M. Earnshaw Health Center | C3: {=XLOOKUP(A3,DB!C:C,DB!K:K)} | D3: {=XLOOKUP(A3,DB!C:C,DB!B:B)} -> 46135 | E3: {=XLOOKUP(A3,DB!C:C,DB!F:F,"" )}
A4: =IFERROR(__xludf.DUMMYFUNCTION("""COMPUTED_VALUE"""),"L4-005-0007D") -> L4-005-0007D | B4: =IFERROR(__xludf.DUMMYFUNCTION("""COMPUTED_VALUE"""),"Department of Finance") -> Department of Finance | D4: {=XLOOKUP(A4,DB!C:C,DB!B:B)} -> #N/A | E4: {=XLOOKUP(A4,DB!C:C,DB!F:F,"" )}
A5: =IFERROR(__xludf.DUMMYFUNCTION("""COMPUTED_VALUE"""),"L4-005-0008F") -> L4-005-0008F | B5: =IFERROR(__xludf.DUMMYFUNCTION("""COMPUTED_VALUE"""),"Bureau of Customs") -> Bureau of Customs | D5: {=XLOOKUP(A5,DB!C:C,DB!B:B)} | E5: {=XLOOKUP(A5,DB!C:C,DB!F:F,"" )} -> 14.744307, 120.972969
A6: =IFERROR(__xludf.DUMMYFUNCTION("""COMPUTED_VALUE"""),"L4-005-05E7A") -> L4-005-05E7A | B6: =IFERROR(__xludf.DUMMYFUNCTION("""COMPUTED_VALUE"""),"San Miguel Health Center") -> San Miguel Health Center | E6: {=XLOOKUP(A6,DB!C:C,DB!F:F,"" )} -> 14.592662, 120.990735
A7: =IFERROR(__xludf.DUMMYFUNCTION("""COMPUTED_VALUE"""),"L4-005-00718") -> L4-005-00718 | B7: =IFERROR(__xludf.DUMMYFUNCTION("""COMPUTED_VALUE"""),"E. delos Santos Elementary School") -> E. delos Santos Elementary School | E7: {=XLOOKUP(A7,DB!C:C,DB!F:F,"" )}
A8: =IFERROR(__xludf.DUMMYFUNCTION("""COMPUTED_VALUE"""),"L4-005-0006D") -> L4-005-0006D | B8: =IFERROR(__xludf.DUMMYFUNCTION("""COMPUTED_VALUE"""),"Intramuros Administration") -> Intramuros Administration | E8: {=XLOOKUP(A8,DB!C:C,DB!F:F,"" )}
A9: =IFERROR(__xludf.DUMMYFUNCTION("""COMPUTED_VALUE"""),"L4-005-06379") -> L4-005-06379 | B9: =IFERROR(__xludf.DUMMYFUNCTION("""COMPUTED_VALUE"""),"Balonbato Barangay Hall") -> Balonbato Barangay Hall | E9: {=XLOOKUP(A9,DB!C:C,DB!F:F,"" )}

Sheet CALOOCAN
A1: TOTAL | B1: =COUNTIF(A3:A1002,"*L4*") -> 4 | D1: =MAIN!C2 -> 46154
A2: Code | B2: SITE | C2: Status | D2: Date visited | E2: Coordinates
A3: =IFERROR(__xludf.DUMMYFUNCTION("QUERY(Master!A2:B1002, ""SELECT A, B WHERE A STARTS WITH 'L4-003'"", 0)"),"L4-003-063CE") -> L4-003-063CE | B3: =IFERROR(__xludf.DUMMYFUNCTION("""COMPUTED_VALUE"""),"Barangay 14 Health Center") -> Barangay 14 Health Center | C3: {=XLOOKUP(A3,DB!C:C,DB!K:K)} -> Defective modem and AP | D3: {=XLOOKUP(A3,DB!C:C,DB!B:B)} -> 46176 | E3: {=XLOOKUP(A3,DB!C:C,DB!F:F,"" )} -> 14.6485132, 120.9647162
A4: =IFERROR(__xludf.DUMMYFUNCTION("""COMPUTED_VALUE"""),"L4-003-007B8") -> L4-003-007B8 | B4: =IFERROR(__xludf.DUMMYFUNCTION("""COMPUTED_VALUE"""),"Bagong Barrio Elementary School") -> Bagong Barrio Elementary School | C4: {=XLOOKUP(A4,DB!C:C,DB!K:K)} -> #N/A | D4: {=XLOOKUP(A4,DB!C:C,DB!B:B)} -> #N/A | E4: {=XLOOKUP(A4,DB!C:C,DB!F:F,"" )}
A5: =IFERROR(__xludf.DUMMYFUNCTION("""COMPUTED_VALUE"""),"L4-003-0017F") -> L4-003-0017F | B5: =IFERROR(__xludf.DUMMYFUNCTION("""COMPUTED_VALUE"""),"Pres. Diosdado Macapagal Memorial Medical Center") -> Pres. Diosdado Macapagal Memorial Medical Center | C5: {=XLOOKUP(A5,DB!C:C,DB!K:K)} -> Defective commbox breaker | D5: {=XLOOKUP(A5,DB!C:C,DB!B:B)} -> 46163 | E5: {=XLOOKUP(A5,DB!C:C,DB!F:F,"" )} -> 14.647097, 120.972037
A6: =IFERROR(__xludf.DUMMYFUNCTION("""COMPUTED_VALUE"""),"L4-003-05893") -> L4-003-05893 | B6: =IFERROR(__xludf.DUMMYFUNCTION("""COMPUTED_VALUE"""),"University of Caloocan City - Camarin Business Campus") -> University of Caloocan City - Camarin Business Campus | C6: {=XLOOKUP(A6,DB!C:C,DB!K:K)} -> Reset modem | D6: {=XLOOKUP(A6,DB!C:C,DB!B:B)} -> 46182 | E6: {=XLOOKUP(A6,DB!C:C,DB!F:F,"" )} -> 14.761965, 121.050172
C7: {=XLOOKUP(A7,DB!C:C,DB!K:K)} -> #N/A | D7: {=XLOOKUP(A7,DB!C:C,DB!B:B)} -> #N/A | E7: {=XLOOKUP(A7,DB!C:C,DB!F:F,"" )}
C8: {=XLOOKUP(A8,DB!C:C,DB!K:K)} -> #N/A | D8: {=XLOOKUP(A8,DB!C:C,DB!B:B)} -> #N/A | E8: {=XLOOKUP(A8,DB!C:C,DB!F:F,"" )}
C9: {=XLOOKUP(A9,DB!C:C,DB!K:K)} -> #N/A | D9: {=XLOOKUP(A9,DB!C:C,DB!B:B)} -> #N/A | E9: {=XLOOKUP(A9,DB!C:C,DB!F:F,"" )}
C10: {=XLOOKUP(A10,DB!C:C,DB!K:K)} -> #N/A | D10: {=XLOOKUP(A10,DB!C:C,DB!B:B)} -> #N/A | E10: {=XLOOKUP(A10,DB!C:C,DB!F:F,"" )}
C11: {=XLOOKUP(A11,DB!C:C,DB!K:K)} -> #N/A | D11: {=XLOOKUP(A11,DB!C:C,DB!B:B)} -> #N/A
C12: {=XLOOKUP(A12,DB!C:C,DB!K:K)} -> #N/A | D12: {=XLOOKUP(A12,DB!C:C,DB!B:B)} -> #N/A
C13: {=XLOOKUP(A13,DB!C:C,DB!K:K)} -> #N/A | D13: {=XLOOKUP(A13,DB!C:C,DB!B:B)} -> #N/A
C14: {=XLOOKUP(A14,DB!C:C,DB!K:K)} -> #N/A | D14: {=XLOOKUP(A14,DB!C:C,DB!B:B)} -> #N/A

Sheet QUEZON CITY
A1: TOTAL | B1: =COUNTIF(A3:A1002,"*L4*") -> 5 | D1: =MAIN!C2 -> 46154
A2: Code | B2: SITE | C2: Status | D2: Date visited | E2: Coordinates
A3: =IFERROR(__xludf.DUMMYFUNCTION("QUERY(Master!A2:B1002, ""SELECT A, B WHERE A STARTS WITH 'L4-011'"", 0)"),"L4-011-00643") -> L4-011-00643 | B3: =IFERROR(__xludf.DUMMYFUNCTION("""COMPUTED_VALUE"""),"San Jose Elementary School - Pag-Ibig sa Nayon Annex") -> San Jose Elementary School - Pag-Ibig sa Nayon Annex | C3: {=XLOOKUP(A3,DB!C:C,DB!K:K)} -> Replaced defective AP | D3: {=XLOOKUP(A3,DB!C:C,DB!B:B)} -> 46182 | E3: {=XLOOKUP(A3,DB!C:C,DB!F:F,"" )} -> 14.646638, 120.996447
A4: =IFERROR(__xludf.DUMMYFUNCTION("""COMPUTED_VALUE"""),"L4-011-00109") -> L4-011-00109 | B4: =IFERROR(__xludf.DUMMYFUNCTION("""COMPUTED_VALUE"""),"East Avenue Medical Center") -> East Avenue Medical Center | C4: {=XLOOKUP(A4,DB!C:C,DB!K:K)} -> #N/A | D4: {=XLOOKUP(A4,DB!C:C,DB!B:B)} -> #N/A | E4: {=XLOOKUP(A4,DB!C:C,DB!F:F,"" )}
A5: =IFERROR(__xludf.DUMMYFUNCTION("""COMPUTED_VALUE"""),"L4-011-00644") -> L4-011-00644 | B5: =IFERROR(__xludf.DUMMYFUNCTION("""COMPUTED_VALUE"""),"Sinag-Tala Elementary School") -> Sinag-Tala Elementary School | C5: {=XLOOKUP(A5,DB!C:C,DB!K:K)} -> Blinking LOS | D5: {=XLOOKUP(A5,DB!C:C,DB!B:B)} -> 46182 | E5: {=XLOOKUP(A5,DB!C:C,DB!F:F,"" )} -> 14.650067, 121.015857
A6: =IFERROR(__xludf.DUMMYFUNCTION("""COMPUTED_VALUE"""),"L4-011-05F58") -> L4-011-05F58 | B6: =IFERROR(__xludf.DUMMYFUNCTION("""COMPUTED_VALUE"""),"Holy Spirit Health Center") -> Holy Spirit Health Center | C6: {=XLOOKUP(A6,DB!C:C,DB!K:K)} | D6: {=XLOOKUP(A6,DB!C:C,DB!B:B)} -> 46129 | E6: {=XLOOKUP(A6,DB!C:C,DB!F:F,"" )}
A7: =IFERROR(__xludf.DUMMYFUNCTION("""COMPUTED_VALUE"""),"L4-011-00626") -> L4-011-00626 | B7: =IFERROR(__xludf.DUMMYFUNCTION("""COMPUTED_VALUE"""),"Libis Elementary School") -> Libis Elementary School | C7: {=XLOOKUP(A7,DB!C:C,DB!K:K)} -> Replaced defective AP | D7: {=XLOOKUP(A7,DB!C:C,DB!B:B)} -> 46184 | E7: {=XLOOKUP(A7,DB!C:C,DB!F:F,"" )} -> 14.615349, 121.073012
C8: {=XLOOKUP(A8,DB!C:C,DB!K:K)} -> #N/A | D8: {=XLOOKUP(A8,DB!C:C,DB!B:B)} -> #N/A | E8: {=XLOOKUP(A8,DB!C:C,DB!F:F,"" )}
C9: {=XLOOKUP(A9,DB!C:C,DB!K:K)} -> #N/A | D9: {=XLOOKUP(A9,DB!C:C,DB!B:B)} -> #N/A | E9: {=XLOOKUP(A9,DB!C:C,DB!F:F,"" )}
C10: {=XLOOKUP(A10,DB!C:C,DB!K:K)} -> #N/A | D10: {=XLOOKUP(A10,DB!C:C,DB!B:B)} -> #N/A | E10: {=XLOOKUP(A10,DB!C:C,DB!F:F,"" )}
C11: {=XLOOKUP(A11,DB!C:C,DB!K:K)} -> #N/A | D11: {=XLOOKUP(A11,DB!C:C,DB!B:B)} -> #N/A | E11: {=XLOOKUP(A11,DB!C:C,DB!F:F,"" )}
C12: {=XLOOKUP(A12,DB!C:C,DB!K:K)} -> #N/A | D12: {=XLOOKUP(A12,DB!C:C,DB!B:B)} -> #N/A | E12: {=XLOOKUP(A12,DB!C:C,DB!F:F,"" )}
C13: {=XLOOKUP(A13,DB!C:C,DB!K:K)} -> #N/A | D13: {=XLOOKUP(A13,DB!C:C,DB!B:B)} -> #N/A | E13: {=XLOOKUP(A13,DB!C:C,DB!F:F,"" )}
C14: {=XLOOKUP(A14,DB!C:C,DB!K:K)} -> #N/A | D14: {=XLOOKUP(A14,DB!C:C,DB!B:B)} -> #N/A | E14: {=XLOOKUP(A14,DB!C:C,DB!F:F,"" )}
C15: {=XLOOKUP(A15,DB!C:C,DB!K:K)} -> #N/A | D15: {=XLOOKUP(A15,DB!C:C,DB!B:B)} -> #N/A | E15: {=XLOOKUP(A15,DB!C:C,DB!F:F,"" )}
C16: {=XLOOKUP(A16,DB!C:C,DB!K:K)} -> #N/A | D16: {=XLOOKUP(A16,DB!C:C,DB!B:B)} -> #N/A | E16: {=XLOOKUP(A16,DB!C:C,DB!F:F,"" )}
C17: {=XLOOKUP(A17,DB!C:C,DB!K:K)} -> #N/A | D17: {=XLOOKUP(A17,DB!C:C,DB!B:B)} -> #N/A | E17: {=XLOOKUP(A17,DB!C:C,DB!F:F,"" )}
C18: {=XLOOKUP(A18,DB!C:C,DB!K:K)} -> #N/A | D18: {=XLOOKUP(A18,DB!C:C,DB!B:B)} -> #N/A | E18: {=XLOOKUP(A18,DB!C:C,DB!F:F,"" )}
C19: {=XLOOKUP(A19,DB!C:C,DB!K:K)} -> #N/A | D19: {=XLOOKUP(A19,DB!C:C,DB!B:B)} -> #N/A | E19: {=XLOOKUP(A19,DB!C:C,DB!F:F,"" )}
C20: {=XLOOKUP(A20,DB!C:C,DB!K:K)} -> #N/A | D20: {=XLOOKUP(A20,DB!C:C,DB!B:B)} -> #N/A
C21: {=XLOOKUP(A21,DB!C:C,DB!K:K)} -> #N/A | D21: {=XLOOKUP(A21,DB!C:C,DB!B:B)} -> #N/A
C22: {=XLOOKUP(A22,DB!C:C,DB!K:K)} -> #N/A | D22: {=XLOOKUP(A22,DB!C:C,DB!B:B)} -> #N/A

Sheet NAVOTAS
A1: TOTAL | B1: =COUNTIF(A3:A1002,"*L4*") -> 1 | D1: =MAIN!C2 -> 46154
A2: Code | B2: SITE | C2: Status | D2: Date visited | E2: Coordinates
A3: =IFERROR(__xludf.DUMMYFUNCTION("QUERY(Master!A2:B1002, ""SELECT A, B WHERE A STARTS WITH 'L4-00A'"", 0)"),"L4-00A-05FAC") -> L4-00A-05FAC | B3: =IFERROR(__xludf.DUMMYFUNCTION("""COMPUTED_VALUE"""),"Bagumbayan Health Center") -> Bagumbayan Health Center | C3: {=XLOOKUP(A3,DB!C:C,DB!K:K)} -> Blinking LOS | D3: {=XLOOKUP(A3,DB!C:C,DB!B:B,"" )} -> 46181 | E3: {=XLOOKUP(A3,DB!C:C,DB!F:F,"" )} -> 14.652732, 120.949088
C4: {=XLOOKUP(A4,DB!C:C,DB!K:K)} -> #N/A | D4: {=XLOOKUP(A4,DB!C:C,DB!B:B,"" )} | E4: {=XLOOKUP(A4,DB!C:C,DB!F:F,"" )}
C5: {=XLOOKUP(A5,DB!C:C,DB!K:K)} -> #N/A | D5: {=XLOOKUP(A5,DB!C:C,DB!B:B,"" )} | E5: {=XLOOKUP(A5,DB!C:C,DB!F:F,"" )}
C6: {=XLOOKUP(A6,DB!C:C,DB!K:K)} -> #N/A | D6: {=XLOOKUP(A6,DB!C:C,DB!B:B,"" )} | E6: {=XLOOKUP(A6,DB!C:C,DB!F:F,"" )}
C7: {=XLOOKUP(A7,DB!C:C,DB!K:K)} -> #N/A | D7: {=XLOOKUP(A7,DB!C:C,DB!B:B,"" )} | E7: {=XLOOKUP(A7,DB!C:C,DB!F:F,"" )}
C8: {=XLOOKUP(A8,DB!C:C,DB!K:K)} -> #N/A | D8: {=XLOOKUP(A8,DB!C:C,DB!B:B,"" )} | E8: {=XLOOKUP(A8,DB!C:C,DB!F:F,"" )}
C9: {=XLOOKUP(A9,DB!C:C,DB!K:K)} -> #N/A | D9: {=XLOOKUP(A9,DB!C:C,DB!B:B,"" )} | E9: {=XLOOKUP(A9,DB!C:C,DB!F:F,"" )}

Sheet VALENZUELA
A1: TOTAL | B1: =COUNTIF(A3:A1002,"*L4*") -> 3 | D1: =MAIN!C2 -> 46154
A2: Code | B2: SITE | C2: Status | D2: Date visited | E2: Coordinates
A3: =IFERROR(__xludf.DUMMYFUNCTION("QUERY(Master!A2:B1002, ""SELECT A, B WHERE A STARTS WITH 'L4-012'"", 0)"),"L4-012-05FE0") -> L4-012-05FE0 | B3: =IFERROR(__xludf.DUMMYFUNCTION("""COMPUTED_VALUE"""),"Tugatog Health Center") -> Tugatog Health Center | C3: {=XLOOKUP(A3,DB!C:C,DB!K:K)} -> Blinking LOS | D3: {=XLOOKUP(A3,DB!C:C,DB!B:B)} -> 46181 | E3: {=XLOOKUP(A3,DB!C:C,DB!F:F,"" )} -> 14.720810, 120.965967
A4: =IFERROR(__xludf.DUMMYFUNCTION("""COMPUTED_VALUE"""),"L4-012-007FF") -> L4-012-007FF | B4: =IFERROR(__xludf.DUMMYFUNCTION("""COMPUTED_VALUE"""),"Punturin Elementary School") -> Punturin Elementary School | C4: {=XLOOKUP(A4,DB!C:C,DB!K:K)} -> Reset modem | D4: {=XLOOKUP(A4,DB!C:C,DB!B:B)} -> 46181 | E4: {=XLOOKUP(A4,DB!C:C,DB!F:F,"" )} -> 14.740331, 120.989604
A5: =IFERROR(__xludf.DUMMYFUNCTION("""COMPUTED_VALUE"""),"L4-012-007F4") -> L4-012-007F4 | B5: =IFERROR(__xludf.DUMMYFUNCTION("""COMPUTED_VALUE"""),"Canumay East Elementary School") -> Canumay East Elementary School | C5: {=XLOOKUP(A5,DB!C:C,DB!K:K)} -> Reset modem | D5: {=XLOOKUP(A5,DB!C:C,DB!B:B)} -> 46181 | E5: {=XLOOKUP(A5,DB!C:C,DB!F:F,"" )} -> 14.719814, 120.993127
C6: {=XLOOKUP(A6,DB!C:C,DB!K:K)} -> #N/A | D6: {=XLOOKUP(A6,DB!C:C,DB!B:B)} -> #N/A | E6: {=XLOOKUP(A6,DB!C:C,DB!F:F,"" )}
C7: {=XLOOKUP(A7,DB!C:C,DB!K:K)} -> #N/A | D7: {=XLOOKUP(A7,DB!C:C,DB!B:B)} -> #N/A | E7: {=XLOOKUP(A7,DB!C:C,DB!F:F,"" )}
C8: {=XLOOKUP(A8,DB!C:C,DB!K:K)} -> #N/A | D8: {=XLOOKUP(A8,DB!C:C,DB!B:B)} -> #N/A | E8: {=XLOOKUP(A8,DB!C:C,DB!F:F,"" )}
C9: {=XLOOKUP(A9,DB!C:C,DB!K:K)} -> #N/A | D9: {=XLOOKUP(A9,DB!C:C,DB!B:B)} -> #N/A | E9: {=XLOOKUP(A9,DB!C:C,DB!F:F,"" )}
C10: {=XLOOKUP(A10,DB!C:C,DB!K:K)} -> #N/A | D10: {=XLOOKUP(A10,DB!C:C,DB!B:B)} -> #N/A | E10: {=XLOOKUP(A10,DB!C:C,DB!F:F,"" )}
C11: {=XLOOKUP(A11,DB!C:C,DB!K:K)} -> #N/A | D11: {=XLOOKUP(A11,DB!C:C,DB!B:B)} -> #N/A | E11: {=XLOOKUP(A11,DB!C:C,DB!F:F,"" )}
C12: {=XLOOKUP(A12,DB!C:C,DB!K:K)} -> #N/A | D12: {=XLOOKUP(A12,DB!C:C,DB!B:B)} -> #N/A | E12: {=XLOOKUP(A12,DB!C:C,DB!F:F,"" )}
C13: {=XLOOKUP(A13,DB!C:C,DB!K:K)} -> #N/A | D13: {=XLOOKUP(A13,DB!C:C,DB!B:B)} -> #N/A | E13: {=XLOOKUP(A13,DB!C:C,DB!F:F,"" )}
C14: {=XLOOKUP(A14,DB!C:C,DB!K:K)} -> #N/A | D14: {=XLOOKUP(A14,DB!C:C,DB!B:B)} -> #N/A | E14: {=XLOOKUP(A14,DB!C:C,DB!F:F,"" )}
C15: {=XLOOKUP(A15,DB!C:C,DB!K:K)} -> #N/A | D15: {=XLOOKUP(A15,DB!C:C,DB!B:B)} -> #N/A
C16: {=XLOOKUP(A16,DB!C:C,DB!K:K)} -> #N/A | D16: {=XLOOKUP(A16,DB!C:C,DB!B:B)} -> #N/A
C17: {=XLOOKUP(A17,DB!C:C,DB!K:K)} -> #N/A | D17: {=XLOOKUP(A17,DB!C:C,DB!B:B)} -> #N/A
C18: {=XLOOKUP(A18,DB!C:C,DB!K:K)} -> #N/A | D18: {=XLOOKUP(A18,DB!C:C,DB!B:B)} -> #N/A
C19: {=XLOOKUP(A19,DB!C:C,DB!K:K)} -> #N/A | D19: {=XLOOKUP(A19,DB!C:C,DB!B:B)} -> #N/A

Sheet MALABON
A1: TOTAL | B1: =COUNTIF(A3:A1002,"*L4*") -> 1 | D1: =MAIN!C2 -> 46154
A2: Code | B2: SITE | C2: Status | D2: Date visited | E2: Coordinates
A3: =IFERROR(__xludf.DUMMYFUNCTION("QUERY(Master!A2:B1002, ""SELECT A, B WHERE A STARTS WITH 'L4-007'"", 0)"),"L4-007-049E0") -> L4-007-049E0 | B3: =IFERROR(__xludf.DUMMYFUNCTION("""COMPUTED_VALUE"""),"Tañong Integrated School") -> Tañong Integrated School | C3: {=XLOOKUP(A3,DB!C:C,DB!K:K)} -> Replaced AP | D3: {=XLOOKUP(A3,DB!C:C,DB!B:B )} -> 46181 | E3: {=XLOOKUP(A3,DB!C:C,DB!F:F,"" )} -> 14.658627, 120.953033
C4: {=XLOOKUP(A4,DB!C:C,DB!K:K)} -> #N/A | D4: {=XLOOKUP(A4,DB!C:C,DB!B:B )} -> #N/A | E4: {=XLOOKUP(A4,DB!C:C,DB!F:F,"" )}
C5: {=XLOOKUP(A5,DB!C:C,DB!K:K)} -> #N/A | D5: {=XLOOKUP(A5,DB!C:C,DB!B:B )} -> #N/A | E5: {=XLOOKUP(A5,DB!C:C,DB!F:F,"" )}
C6: {=XLOOKUP(A6,DB!C:C,DB!K:K)} -> #N/A | D6: {=XLOOKUP(A6,DB!C:C,DB!B:B )} -> #N/A | E6: {=XLOOKUP(A6,DB!C:C,DB!F:F,"" )}
C7: {=XLOOKUP(A7,DB!C:C,DB!K:K)} -> #N/A | D7: {=XLOOKUP(A7,DB!C:C,DB!B:B )} -> #N/A | E7: {=XLOOKUP(A7,DB!C:C,DB!F:F,"" )}
C8: {=XLOOKUP(A8,DB!C:C,DB!K:K)} -> #N/A | D8: {=XLOOKUP(A8,DB!C:C,DB!B:B )} -> #N/A | E8: {=XLOOKUP(A8,DB!C:C,DB!F:F,"" )}
C9: {=XLOOKUP(A9,DB!C:C,DB!K:K)} -> #N/A | D9: {=XLOOKUP(A9,DB!C:C,DB!B:B )} -> #N/A | E9: {=XLOOKUP(A9,DB!C:C,DB!F:F,"" )}
C10: {=XLOOKUP(A10,DB!C:C,DB!K:K)} -> #N/A | D10: {=XLOOKUP(A10,DB!C:C,DB!B:B )} -> #N/A | E10: {=XLOOKUP(A10,DB!C:C,DB!F:F,"" )}
C11: {=XLOOKUP(A11,DB!C:C,DB!K:K)} -> #N/A | D11: {=XLOOKUP(A11,DB!C:C,DB!B:B )} -> #N/A | E11: {=XLOOKUP(A11,DB!C:C,DB!F:F,"" )}
C12: {=XLOOKUP(A12,DB!C:C,DB!K:K)} -> #N/A | D12: {=XLOOKUP(A12,DB!C:C,DB!B:B )} -> #N/A
C13: {=XLOOKUP(A13,DB!C:C,DB!K:K)} -> #N/A | D13: {=XLOOKUP(A13,DB!C:C,DB!B:B )} -> #N/A
C14: {=XLOOKUP(A14,DB!C:C,DB!K:K)} -> #N/A | D14: {=XLOOKUP(A14,DB!C:C,DB!B:B )} -> #N/A
C15: {=XLOOKUP(A15,DB!C:C,DB!K:K)} -> #N/A | D15: {=XLOOKUP(A15,DB!C:C,DB!B:B )} -> #N/A
C16: {=XLOOKUP(A16,DB!C:C,DB!K:K)} -> #N/A | D16: {=XLOOKUP(A16,DB!C:C,DB!B:B )} -> #N/A
C17: {=XLOOKUP(A17,DB!C:C,DB!K:K)} -> #N/A | D17: {=XLOOKUP(A17,DB!C:C,DB!B:B )} -> #N/A
C18: {=XLOOKUP(A18,DB!C:C,DB!K:K)} -> #N/A | D18: {=XLOOKUP(A18,DB!C:C,DB!B:B )} -> #N/A
C19: {=XLOOKUP(A19,DB!C:C,DB!K:K)} -> #N/A | D19: {=XLOOKUP(A19,DB!C:C,DB!B:B )} -> #N/A
C20: {=XLOOKUP(A20,DB!C:C,DB!K:K)} -> #N/A | D20: {=XLOOKUP(A20,DB!C:C,DB!B:B )} -> #N/A

Sheet Marikina
A1: TOTAL | B1: =COUNTIF(A3:A1001,"*L4*") -> 0 | D1: =MAIN!C2 -> 46154
A2: Code | B2: SITE | C2: Status | D2: Date visited | E2: Coordinates
A3: =IFERROR(__xludf.DUMMYFUNCTION("QUERY(Master!A2:B1001, ""SELECT A, B WHERE A STARTS WITH 'L4-006'"", 0)"),"#N/A") -> #N/A | C3: {=XLOOKUP(A3,DB!C:C,DB!K:K)} -> #N/A | D3: {=XLOOKUP(A3,DB!C:C,DB!B:B)} -> #N/A | E3: {=XLOOKUP(A3,DB!C:C,DB!F:F,"" )} -> #N/A
C4: {=XLOOKUP(A4,DB!C:C,DB!K:K)} -> #N/A | D4: {=XLOOKUP(A4,DB!C:C,DB!B:B)} -> #N/A | E4: {=XLOOKUP(A4,DB!C:C,DB!F:F,"" )}
C5: {=XLOOKUP(A5,DB!C:C,DB!K:K)} -> #N/A | D5: {=XLOOKUP(A5,DB!C:C,DB!B:B)} -> #N/A | E5: {=XLOOKUP(A5,DB!C:C,DB!F:F,"" )}
C6: {=XLOOKUP(A6,DB!C:C,DB!K:K)} -> #N/A | D6: {=XLOOKUP(A6,DB!C:C,DB!B:B)} -> #N/A | E6: {=XLOOKUP(A6,DB!C:C,DB!F:F,"" )}
C7: {=XLOOKUP(A7,DB!C:C,DB!K:K)} -> #N/A | D7: {=XLOOKUP(A7,DB!C:C,DB!B:B)} -> #N/A | E7: {=XLOOKUP(A7,DB!C:C,DB!F:F,"" )}
C8: {=XLOOKUP(A8,DB!C:C,DB!K:K)} -> #N/A | D8: {=XLOOKUP(A8,DB!C:C,DB!B:B)} -> #N/A | E8: {=XLOOKUP(A8,DB!C:C,DB!F:F,"" )}
C9: {=XLOOKUP(A9,DB!C:C,DB!K:K)} -> #N/A | D9: {=XLOOKUP(A9,DB!C:C,DB!B:B)} -> #N/A | E9: {=XLOOKUP(A9,DB!C:C,DB!F:F,"" )}
C10: {=XLOOKUP(A10,DB!C:C,DB!K:K)} -> #N/A | D10: {=XLOOKUP(A10,DB!C:C,DB!B:B)} -> #N/A | E10: {=XLOOKUP(A10,DB!C:C,DB!F:F,"" )}

Sheet MAKATI
A1: TOTAL | B1: =COUNTIF(A3:A1002,"*L4*") -> 4 | D1: =MAIN!C2 -> 46154
A2: Code | B2: SITE | C2: Status | D2: Date visited | E2: Coordinates
A3: =IFERROR(__xludf.DUMMYFUNCTION("QUERY(Master!A2:B1002, ""SELECT A, B WHERE A STARTS WITH 'L4-008'"", 0)"),"L4-008-00010") -> L4-008-00010 | B3: =IFERROR(__xludf.DUMMYFUNCTION("""COMPUTED_VALUE"""),"Board of Investments") -> Board of Investments | C3: {=XLOOKUP(A3,DB!C:C,DB!K:K)} | D3: {=XLOOKUP(A3,DB!C:C,DB!B:B)} -> 45780
A4: =IFERROR(__xludf.DUMMYFUNCTION("""COMPUTED_VALUE"""),"L4-008-006F2") -> L4-008-006F2 | B4: =IFERROR(__xludf.DUMMYFUNCTION("""COMPUTED_VALUE"""),"Hen. Pio del Pilar Elementary School I") -> Hen. Pio del Pilar Elementary School I | D4: {=XLOOKUP(A4,DB!C:C,DB!B:B)} -> #N/A
A5: =IFERROR(__xludf.DUMMYFUNCTION("""COMPUTED_VALUE"""),"L4-008-00701") -> L4-008-00701 | B5: =IFERROR(__xludf.DUMMYFUNCTION("""COMPUTED_VALUE"""),"Makati Elementary School") -> Makati Elementary School | D5: {=XLOOKUP(A5,DB!C:C,DB!B:B)} -> #N/A
A6: =IFERROR(__xludf.DUMMYFUNCTION("""COMPUTED_VALUE"""),"L4-008-06395") -> L4-008-06395 | B6: =IFERROR(__xludf.DUMMYFUNCTION("""COMPUTED_VALUE"""),"Philippine National Police Aviation Security Group") -> Philippine National Police Aviation Security Group

Sheet SAN JUAN
A1: TOTAL | B1: =COUNTIF(A3:A1002,"*L4*") -> 0 | D1: =MAIN!C2 -> 46154
A2: Code | B2: SITE | C2: Status | D2: Date visited | E2: Coordinates
A3: =IFERROR(__xludf.DUMMYFUNCTION("QUERY(Master!A2:B1002, ""SELECT A, B WHERE A STARTS WITH 'L4-014'"", 0)"),"#N/A") -> #N/A | C3: {=XLOOKUP(A3,DB!C:C,DB!K:K)} -> #N/A | D3: {=XLOOKUP(A3,DB!C:C,DB!B:B)} -> #N/A
D4: {=XLOOKUP(A4,DB!C:C,DB!B:B)} -> #N/A
D5: {=XLOOKUP(A5,DB!C:C,DB!B:B)} -> #N/A

Sheet PASIG
A1: TOTAL | B1: =COUNTIF(A3:A1002,"*L4*") -> 0 | D1: =MAIN!C2 -> 46154
A2: Code | B2: SITE | C2: Status | D2: Date visited | E2: Coordinates
A3: =IFERROR(__xludf.DUMMYFUNCTION("QUERY(Master!A2:B1002, ""SELECT A, B WHERE A STARTS WITH 'L4-009'"", 0)"),"#N/A") -> #N/A | C3: {=XLOOKUP(A3,DB!C:C,DB!K:K)} -> #N/A | D3: {=XLOOKUP(A3,DB!C:C,DB!B:B)} -> #N/A
C4: {=XLOOKUP(A4,DB!C:C,DB!K:K)} -> #N/A | D4: {=XLOOKUP(A4,DB!C:C,DB!B:B)} -> #N/A
C5: {=XLOOKUP(A5,DB!C:C,DB!K:K)} -> #N/A | D5: {=XLOOKUP(A5,DB!C:C,DB!B:B)} -> #N/A
C6: {=XLOOKUP(A6,DB!C:C,DB!K:K)} -> #N/A | D6: {=XLOOKUP(A6,DB!C:C,DB!B:B)} -> #N/A
C7: {=XLOOKUP(A7,DB!C:C,DB!K:K)} -> #N/A | D7: {=XLOOKUP(A7,DB!C:C,DB!B:B)} -> #N/A
C8: {=XLOOKUP(A8,DB!C:C,DB!K:K)} -> #N/A | D8: {=XLOOKUP(A8,DB!C:C,DB!B:B)} -> #N/A
C9: {=XLOOKUP(A9,DB!C:C,DB!K:K)} -> #N/A | D9: {=XLOOKUP(A9,DB!C:C,DB!B:B)} -> #N/A
C10: {=XLOOKUP(A10,DB!C:C,DB!K:K)} -> #N/A | D10: {=XLOOKUP(A10,DB!C:C,DB!B:B)} -> #N/A
C11: {=XLOOKUP(A11,DB!C:C,DB!K:K)} -> #N/A | D11: {=XLOOKUP(A11,DB!C:C,DB!B:B)} -> #N/A
C12: {=XLOOKUP(A12,DB!C:C,DB!K:K)} -> #N/A | D12: {=XLOOKUP(A12,DB!C:C,DB!B:B)} -> #N/A
C13: {=XLOOKUP(A13,DB!C:C,DB!K:K)} -> #N/A | D13: {=XLOOKUP(A13,DB!C:C,DB!B:B)} -> #N/A

Sheet MANDALUYONG
A1: TOTAL | B1: =COUNTIF(A3:A1002,"*L4*") -> 0 | D1: =MAIN!C2 -> 46154
A2: Code | B2: SITE | C2: Status | D2: Date visited | E2: Coordinates
A3: =IFERROR(__xludf.DUMMYFUNCTION("QUERY(Master!A2:B1002, ""SELECT A, B WHERE A STARTS WITH 'L4-002'"", 0)"),"#N/A") -> #N/A | C3: {=XLOOKUP(A3,DB!C:C,DB!K:K)} -> #N/A | D3: {=XLOOKUP(A3,DB!C:C,DB!B:B,)} -> #N/A | E3: {=XLOOKUP(A3,DB!C:C,DB!F:F,"" )} -> #N/A
C4: {=XLOOKUP(A4,DB!C:C,DB!K:K)} -> #N/A | D4: {=XLOOKUP(A4,DB!C:C,DB!B:B,)} | E4: {=XLOOKUP(A4,DB!C:C,DB!F:F,"" )}
C5: {=XLOOKUP(A5,DB!C:C,DB!K:K)} -> #N/A | D5: {=XLOOKUP(A5,DB!C:C,DB!B:B,)} | E5: {=XLOOKUP(A5,DB!C:C,DB!F:F,"" )}
C6: {=XLOOKUP(A6,DB!C:C,DB!K:K)} -> #N/A | D6: {=XLOOKUP(A6,DB!C:C,DB!B:B,)} | E6: {=XLOOKUP(A6,DB!C:C,DB!F:F,"" )}
C7: {=XLOOKUP(A7,DB!C:C,DB!K:K)} -> #N/A | D7: {=XLOOKUP(A7,DB!C:C,DB!B:B,)} | E7: {=XLOOKUP(A7,DB!C:C,DB!F:F,"" )}
C8: {=XLOOKUP(A8,DB!C:C,DB!K:K)} -> #N/A | D8: {=XLOOKUP(A8,DB!C:C,DB!B:B,)} | E8: {=XLOOKUP(A8,DB!C:C,DB!F:F,"" )}
C9: {=XLOOKUP(A9,DB!C:C,DB!K:K)} -> #N/A | D9: {=XLOOKUP(A9,DB!C:C,DB!B:B,)} | E9: {=XLOOKUP(A9,DB!C:C,DB!F:F,"" )}
C10: {=XLOOKUP(A10,DB!C:C,DB!K:K)} -> #N/A | D10: {=XLOOKUP(A10,DB!C:C,DB!B:B,)} | E10: {=XLOOKUP(A10,DB!C:C,DB!F:F,"" )}
C11: {=XLOOKUP(A11,DB!C:C,DB!K:K)} -> #N/A | D11: {=XLOOKUP(A11,DB!C:C,DB!B:B,)} | E11: {=XLOOKUP(A11,DB!C:C,DB!F:F,"" )}

Sheet Pasay
A1: TOTAL | B1: =COUNTIF(A3:A1002,"*L4*") -> 1 | D1: =MAIN!C2 -> 46154
A2: Code | B2: SITE | C2: Status | D2: Date visited | E2: Coordinates
A3: =IFERROR(__xludf.DUMMYFUNCTION("QUERY(Master!A2:B1002, ""SELECT A, B WHERE A STARTS WITH 'L4-015'"", 0)"),"L4-015-0004B") -> L4-015-0004B | B3: =IFERROR(__xludf.DUMMYFUNCTION("""COMPUTED_VALUE"""),"Overseas Workers Welfare Administration") -> Overseas Workers Welfare Administration | C3: {=XLOOKUP(A3,DB!C:C,DB!K:K)} | D3: {=XLOOKUP(A3,DB!C:C,DB!B:B)} | E3: {=XLOOKUP(A3,DB!C:C,DB!F:F,"" )}
D4: {=XLOOKUP(A4,DB!C:C,DB!B:B)} -> #N/A | E4: {=XLOOKUP(A4,DB!C:C,DB!F:F,"" )}
E5: {=XLOOKUP(A5,DB!C:C,DB!F:F,"" )}
E6: {=XLOOKUP(A6,DB!C:C,DB!F:F,"" )}
E7: {=XLOOKUP(A7,DB!C:C,DB!F:F,"" )}
E8: {=XLOOKUP(A8,DB!C:C,DB!F:F,"" )}
E9: {=XLOOKUP(A9,DB!C:C,DB!F:F,"" )}
E10: {=XLOOKUP(A10,DB!C:C,DB!F:F,"" )}

Sheet Paranaque
A1: TOTAL | B1: =COUNTIF(A3:A1002,"*L4*") -> 1 | D1: =MAIN!C2 -> 46154
A2: Code | B2: SITE | C2: Status | D2: Date visited | E2: Coordinates
A3: =IFERROR(__xludf.DUMMYFUNCTION("QUERY(Master!A2:B1002, ""SELECT A, B WHERE A STARTS WITH 'L4-013'"", 0)"),"L4-013-05ED0") -> L4-013-05ED0 | B3: =IFERROR(__xludf.DUMMYFUNCTION("""COMPUTED_VALUE"""),"Vitalez Health Center") -> Vitalez Health Center | C3: {=XLOOKUP(A3,DB!C:C,DB!K:K)} -> #N/A | D3: {=XLOOKUP(A3,DB!C:C,DB!B:B)} -> #N/A | E3: {=XLOOKUP(A3,DB!C:C,DB!F:F,"" )}
C4: {=XLOOKUP(A4,DB!C:C,DB!K:K)} -> #N/A | D4: {=XLOOKUP(A4,DB!C:C,DB!B:B)} -> #N/A | E4: {=XLOOKUP(A4,DB!C:C,DB!F:F,"" )}
C5: {=XLOOKUP(A5,DB!C:C,DB!K:K)} -> #N/A | D5: {=XLOOKUP(A5,DB!C:C,DB!B:B)} -> #N/A | E5: {=XLOOKUP(A5,DB!C:C,DB!F:F,"" )}
C6: {=XLOOKUP(A6,DB!C:C,DB!K:K)} -> #N/A | D6: {=XLOOKUP(A6,DB!C:C,DB!B:B)} -> #N/A | E6: {=XLOOKUP(A6,DB!C:C,DB!F:F,"" )}
C7: {=XLOOKUP(A7,DB!C:C,DB!K:K)} -> #N/A | D7: {=XLOOKUP(A7,DB!C:C,DB!B:B)} -> #N/A | E7: {=XLOOKUP(A7,DB!C:C,DB!F:F,"" )}
C8: {=XLOOKUP(A8,DB!C:C,DB!K:K)} -> #N/A | D8: {=XLOOKUP(A8,DB!C:C,DB!B:B)} -> #N/A | E8: {=XLOOKUP(A8,DB!C:C,DB!F:F,"" )}
E9: {=XLOOKUP(A9,DB!C:C,DB!F:F,"" )}
E10: {=XLOOKUP(A10,DB!C:C,DB!F:F,"" )}

Sheet LAS PINAS
A1: TOTAL | B1: =COUNTIF(A3:A1002,"*L4*") -> 0 | D1: =MAIN!C2 -> 46154
A2: Code | B2: SITE | C2: Status | D2: Date visited | E2: Coordinates
A3: =IFERROR(__xludf.DUMMYFUNCTION("QUERY(Master!A2:B1002, ""SELECT A, B WHERE A STARTS WITH 'L4-004'"", 0)"),"#N/A") -> #N/A | C3: {=XLOOKUP(A3,DB!C:C,DB!K:K)} -> #N/A | D3: {=XLOOKUP(A3,DB!C:C,DB!B:B)} -> #N/A | E3: {=XLOOKUP(A3,DB!C:C,DB!F:F,"" )} -> #N/A
C4: {=XLOOKUP(A4,DB!C:C,DB!K:K)} -> #N/A | D4: {=XLOOKUP(A4,DB!C:C,DB!B:B)} -> #N/A | E4: {=XLOOKUP(A4,DB!C:C,DB!F:F,"" )}
C5: {=XLOOKUP(A5,DB!C:C,DB!K:K)} -> #N/A | D5: {=XLOOKUP(A5,DB!C:C,DB!B:B)} -> #N/A | E5: {=XLOOKUP(A5,DB!C:C,DB!F:F,"" )}
C6: {=XLOOKUP(A6,DB!C:C,DB!K:K)} -> #N/A | D6: {=XLOOKUP(A6,DB!C:C,DB!B:B)} -> #N/A | E6: {=XLOOKUP(A6,DB!C:C,DB!F:F,"" )}
C7: {=XLOOKUP(A7,DB!C:C,DB!K:K)} -> #N/A | D7: {=XLOOKUP(A7,DB!C:C,DB!B:B)} -> #N/A | E7: {=XLOOKUP(A7,DB!C:C,DB!F:F,"" )}
C8: {=XLOOKUP(A8,DB!C:C,DB!K:K)} -> #N/A | D8: {=XLOOKUP(A8,DB!C:C,DB!B:B)} -> #N/A | E8: {=XLOOKUP(A8,DB!C:C,DB!F:F,"" )}
C9: {=XLOOKUP(A9,DB!C:C,DB!K:K)} -> #N/A | D9: {=XLOOKUP(A9,DB!C:C,DB!B:B)} -> #N/A | E9: {=XLOOKUP(A9,DB!C:C,DB!F:F,"" )}
C10: {=XLOOKUP(A10,DB!C:C,DB!K:K)} -> #N/A | D10: {=XLOOKUP(A10,DB!C:C,DB!B:B)} -> #N/A | E10: {=XLOOKUP(A10,DB!C:C,DB!F:F,"" )}
C11: {=XLOOKUP(A11,DB!C:C,DB!K:K)} -> #N/A | D11: {=XLOOKUP(A11,DB!C:C,DB!B:B)} -> #N/A | E11: {=XLOOKUP(A11,DB!C:C,DB!F:F,"" )}
C12: {=XLOOKUP(A12,DB!C:C,DB!K:K)} -> #N/A | D12: {=XLOOKUP(A12,DB!C:C,DB!B:B)} -> #N/A | E12: {=XLOOKUP(A12,DB!C:C,DB!F:F,"" )}

Sheet MUNTINLUPA
A1: TOTAL | B1: =COUNTIF(A3:A1002,"*L4*") -> 2 | D1: =MAIN!C2 -> 46154
A2: Code | B2: SITE | C2: Status | D2: Date visited | E2: Coordinates
A3: =IFERROR(__xludf.DUMMYFUNCTION("QUERY(Master!A2:B1002, ""SELECT A, B WHERE A STARTS WITH 'L4-00B'"", 0)"),"L4-00B-04CFF") -> L4-00B-04CFF | B3: =IFERROR(__xludf.DUMMYFUNCTION("""COMPUTED_VALUE"""),"Muntinlupa National High School") -> Muntinlupa National High School | C3: {=XLOOKUP(A3,DB!C:C,DB!K:K)} -> Replaced AP | D3: {=XLOOKUP(A3,DB!C:C,DB!B:B)} -> 46183 | E3: {=XLOOKUP(A3,DB!C:C,DB!F:F,"" )} -> 14.388728, 121.027980
A4: =IFERROR(__xludf.DUMMYFUNCTION("""COMPUTED_VALUE"""),"L4-00B-00686") -> L4-00B-00686 | B4: =IFERROR(__xludf.DUMMYFUNCTION("""COMPUTED_VALUE"""),"Soldiers' Hills Elementary School ") -> Soldiers' Hills Elementary School | C4: {=XLOOKUP(A4,DB!C:C,DB!K:K)} -> (AP DEFECTIVE) Blinking LOS | D4: {=XLOOKUP(A4,DB!C:C,DB!B:B)} -> 46183 | E4: {=XLOOKUP(A4,DB!C:C,DB!F:F,"" )} -> 14.400877, 121.036763
C5: {=XLOOKUP(A5,DB!C:C,DB!K:K)} -> #N/A | D5: {=XLOOKUP(A5,DB!C:C,DB!B:B)} -> #N/A | E5: {=XLOOKUP(A5,DB!C:C,DB!F:F,"" )}
C6: {=XLOOKUP(A6,DB!C:C,DB!K:K)} -> #N/A | D6: {=XLOOKUP(A6,DB!C:C,DB!B:B)} -> #N/A | E6: {=XLOOKUP(A6,DB!C:C,DB!F:F,"" )}
C7: {=XLOOKUP(A7,DB!C:C,DB!K:K)} -> #N/A | D7: {=XLOOKUP(A7,DB!C:C,DB!B:B)} -> #N/A | E7: {=XLOOKUP(A7,DB!C:C,DB!F:F,"" )}
C8: {=XLOOKUP(A8,DB!C:C,DB!K:K)} -> #N/A | D8: {=XLOOKUP(A8,DB!C:C,DB!B:B)} -> #N/A
C9: {=XLOOKUP(A9,DB!C:C,DB!K:K)} -> #N/A | D9: {=XLOOKUP(A9,DB!C:C,DB!B:B)} -> #N/A

Sheet TAGUIG
A1: TOTAL | B1: =COUNTIF(A3:A1002,"*L4*") -> 0 | D1: =MAIN!C2 -> 46154
A2: Code | B2: SITE | C2: Status | D2: Date visited | E2: Coordinates
A3: =IFERROR(__xludf.DUMMYFUNCTION("QUERY(Master!A2:B1002, ""SELECT A, B WHERE A STARTS WITH 'L4-022'"", 0)"),"#N/A") -> #N/A | C3: {=XLOOKUP(A3,DB!C:C,DB!K:K)} -> #N/A | D3: {=XLOOKUP(A3,DB!C:C,DB!B:B)} -> #N/A | E3: {=XLOOKUP(A3,DB!C:C,DB!F:F,"" )} -> #N/A
C4: {=XLOOKUP(A4,DB!C:C,DB!K:K)} -> #N/A | D4: {=XLOOKUP(A4,DB!C:C,DB!B:B)} -> #N/A | E4: {=XLOOKUP(A4,DB!C:C,DB!F:F,"" )}
C5: {=XLOOKUP(A5,DB!C:C,DB!K:K)} -> #N/A | D5: {=XLOOKUP(A5,DB!C:C,DB!B:B)} -> #N/A | E5: {=XLOOKUP(A5,DB!C:C,DB!F:F,"" )}
D6: {=XLOOKUP(A6,DB!C:C,DB!B:B)} -> #N/A

Sheet NEW
A1: TOTAL | B1: =COUNTIF(A3:A1002,"*L4*") -> 18 | D1: =MAIN!C2 -> 46154
A2: Code | B2: SITE | C2: Status | D2: Date visited | E2: Coordinates
C3: {=XLOOKUP(A3,DB!C:C,DB!K:K)} -> #N/A | D3: {=XLOOKUP(A3,DB!C:C,DB!B:B,)} | E3: {=XLOOKUP(A3,DB!C:C,DB!F:F,"" )}
A4: Caloocan City
A5: L4-003-007B8 | B5: Bagong Barrio Elementary School | C5: (OFFLINE MAY 25)
A6: L4-003-0017F | B6: Pres. Diosdado Macapagal Memorial Medical Center (NO POWER DEFECTIVE COMMBOX BREAKER)
A7: L4-003-05F8B | B7: Camarin "D" Health Center (OFFLINE MAY 12)
A9: Las Piñas City
A10: L4-004-05E99 | B10: Pulanglupa Dos Health Center | C10: (OFFLINE MAY 26)
A12: Makati City
A13: L4-008-00010 | B13: Board of Investments | C13: (OFFLINE MAY 21)
A14: L4-008-00701 | B14: Makati Elementary School (OFFLINE MAY 26)
A16: Malabon City
A17: L4-007-049E0 | B17: Tañong Integrated School (DEFECTIVE AP)
A19: Manila City
A20: L4-005-05E5A | B20: M. Earnshaw Health Center (SITE INSPECTION)
A21: L4-005-0007D | B21: Department of Finance | C21: (DEFECTIVE AP)
A22: L4-005-0008F | B22: Bureau of Customs (OFFLINE MAY 22)
A23: L4-005-04DA8 | B23: Pres. Sergio Osmena, Sr. High School (DEFECTIVE AP)
A24: L4-005-0006D | B24: Intramuros Administration (OFFLINE MAY 12)
A26: Muntinlupa City
A27: L4-00B-04CFF | B27: Muntinlupa National High School | C27: (DEFECTIVE AP)
A28: L4-00B-00686 | B28: Soldiers' Hills Elementary School | C28: (DEFECTIVE AP)
A30: Parañaque City
A31: L4-013-05ED0 | B31: Vitalez Health Center (SCHEDULE FOR SITE RELOCATION)
A32: L4-013-05EC1 | B32: Don Bosco Health Center
A34: Pasay City
A35: L4-008-06395 | B35: Philippine National Police Aviation Security Group (OFFLINE MAY 12)
A36: L4-015-0004B | B36: Overseas Workers Welfare Administration | C36: (DEFECTIVE AP)

Sheet Tugon
A1: Column 1 | B1: Column 2 | C1: Column 3 | D1: Column 4 | E1: Column 5
A5: Caloocan City
A6: L4-003-007B8 | B6: Bagong Barrio Elementary School | C6: =IFERROR(__xludf.DUMMYFUNCTION("IFERROR(REGEXEXTRACT(B6,""\(([^)]*)\)""),"""")"),"") | D6: =IFERROR(__xludf.DUMMYFUNCTION("TRIM(REGEXREPLACE(B6,""\s*\(.*?\)"",""""))"),"Bagong Barrio Elementary School") -> Bagong Barrio Elementary School
A7: L4-003-0017F | B7: Pres. Diosdado Macapagal Memorial Medical Center (NO POWER DEFECTIVE COMMBOX BREAKER) | C7: =IFERROR(__xludf.DUMMYFUNCTION("IFERROR(REGEXEXTRACT(B7,""\(([^)]*)\)""),"""")"),"NO POWER DEFECTIVE COMMBOX BREAKER") -> NO POWER DEFECTIVE COMMBOX BREAKER | D7: =IFERROR(__xludf.DUMMYFUNCTION("TRIM(REGEXREPLACE(B7,""\s*\(.*?\)"",""""))"),"Pres. Diosdado Macapagal Memorial Medical Center") -> Pres. Diosdado Macapagal Memorial Medical Center
A8: L4-003-05F8B | B8: Camarin "D" Health Center (OFFLINE MAY 12) | C8: =IFERROR(__xludf.DUMMYFUNCTION("IFERROR(REGEXEXTRACT(B8,""\(([^)]*)\)""),"""")"),"OFFLINE MAY 12") -> OFFLINE MAY 12 | D8: =IFERROR(__xludf.DUMMYFUNCTION("TRIM(REGEXREPLACE(B8,""\s*\(.*?\)"",""""))"),"Camarin ""D"" Health Center") -> Camarin "D" Health Center
C9: =IFERROR(__xludf.DUMMYFUNCTION("IFERROR(REGEXEXTRACT(B9,""\(([^)]*)\)""),"""")"),"") | D9: =IFERROR(__xludf.DUMMYFUNCTION("TRIM(REGEXREPLACE(B9,""\s*\(.*?\)"",""""))"),"")
A10: Las Piñas City | C10: =IFERROR(__xludf.DUMMYFUNCTION("IFERROR(REGEXEXTRACT(B10,""\(([^)]*)\)""),"""")"),"") | D10: =IFERROR(__xludf.DUMMYFUNCTION("TRIM(REGEXREPLACE(B10,""\s*\(.*?\)"",""""))"),"")
A11: L4-004-05E99 | B11: Pulanglupa Dos Health Center | C11: =IFERROR(__xludf.DUMMYFUNCTION("IFERROR(REGEXEXTRACT(B11,""\(([^)]*)\)""),"""")"),"") | D11: =IFERROR(__xludf.DUMMYFUNCTION("TRIM(REGEXREPLACE(B11,""\s*\(.*?\)"",""""))"),"Pulanglupa Dos Health Center") -> Pulanglupa Dos Health Center
C12: =IFERROR(__xludf.DUMMYFUNCTION("IFERROR(REGEXEXTRACT(B12,""\(([^)]*)\)""),"""")"),"") | D12: =IFERROR(__xludf.DUMMYFUNCTION("TRIM(REGEXREPLACE(B12,""\s*\(.*?\)"",""""))"),"")
A13: Makati City | C13: =IFERROR(__xludf.DUMMYFUNCTION("IFERROR(REGEXEXTRACT(B13,""\(([^)]*)\)""),"""")"),"") | D13: =IFERROR(__xludf.DUMMYFUNCTION("TRIM(REGEXREPLACE(B13,""\s*\(.*?\)"",""""))"),"")
A14: L4-008-00010 | B14: Board of Investments | C14: =IFERROR(__xludf.DUMMYFUNCTION("IFERROR(REGEXEXTRACT(B14,""\(([^)]*)\)""),"""")"),"") | D14: =IFERROR(__xludf.DUMMYFUNCTION("TRIM(REGEXREPLACE(B14,""\s*\(.*?\)"",""""))"),"Board of Investments") -> Board of Investments
A15: L4-008-00701 | B15: Makati Elementary School (OFFLINE MAY 26) | C15: =IFERROR(__xludf.DUMMYFUNCTION("IFERROR(REGEXEXTRACT(B15,""\(([^)]*)\)""),"""")"),"OFFLINE MAY 26") -> OFFLINE MAY 26 | D15: =IFERROR(__xludf.DUMMYFUNCTION("TRIM(REGEXREPLACE(B15,""\s*\(.*?\)"",""""))"),"Makati Elementary School") -> Makati Elementary School
C16: =IFERROR(__xludf.DUMMYFUNCTION("IFERROR(REGEXEXTRACT(B16,""\(([^)]*)\)""),"""")"),"") | D16: =IFERROR(__xludf.DUMMYFUNCTION("TRIM(REGEXREPLACE(B16,""\s*\(.*?\)"",""""))"),"")
A17: Malabon City | C17: =IFERROR(__xludf.DUMMYFUNCTION("IFERROR(REGEXEXTRACT(B17,""\(([^)]*)\)""),"""")"),"") | D17: =IFERROR(__xludf.DUMMYFUNCTION("TRIM(REGEXREPLACE(B17,""\s*\(.*?\)"",""""))"),"")
A18: L4-007-049E0 | B18: Tañong Integrated School (DEFECTIVE AP) | C18: =IFERROR(__xludf.DUMMYFUNCTION("IFERROR(REGEXEXTRACT(B18,""\(([^)]*)\)""),"""")"),"DEFECTIVE AP") -> DEFECTIVE AP | D18: =IFERROR(__xludf.DUMMYFUNCTION("TRIM(REGEXREPLACE(B18,""\s*\(.*?\)"",""""))"),"Tañong Integrated School") -> Tañong Integrated School
C19: =IFERROR(__xludf.DUMMYFUNCTION("IFERROR(REGEXEXTRACT(B19,""\(([^)]*)\)""),"""")"),"") | D19: =IFERROR(__xludf.DUMMYFUNCTION("TRIM(REGEXREPLACE(B19,""\s*\(.*?\)"",""""))"),"")
A20: Manila City | C20: =IFERROR(__xludf.DUMMYFUNCTION("IFERROR(REGEXEXTRACT(B20,""\(([^)]*)\)""),"""")"),"") | D20: =IFERROR(__xludf.DUMMYFUNCTION("TRIM(REGEXREPLACE(B20,""\s*\(.*?\)"",""""))"),"")
A21: L4-005-05E5A | B21: M. Earnshaw Health Center (SITE INSPECTION) | C21: =IFERROR(__xludf.DUMMYFUNCTION("IFERROR(REGEXEXTRACT(B21,""\(([^)]*)\)""),"""")"),"SITE INSPECTION") -> SITE INSPECTION | D21: =IFERROR(__xludf.DUMMYFUNCTION("TRIM(REGEXREPLACE(B21,""\s*\(.*?\)"",""""))"),"M. Earnshaw Health Center") -> M. Earnshaw Health Center
A22: L4-005-0007D | B22: Department of Finance | C22: =IFERROR(__xludf.DUMMYFUNCTION("IFERROR(REGEXEXTRACT(B22,""\(([^)]*)\)""),"""")"),"") | D22: =IFERROR(__xludf.DUMMYFUNCTION("TRIM(REGEXREPLACE(B22,""\s*\(.*?\)"",""""))"),"Department of Finance") -> Department of Finance
A23: L4-005-0008F | B23: Bureau of Customs (OFFLINE MAY 22) | C23: =IFERROR(__xludf.DUMMYFUNCTION("IFERROR(REGEXEXTRACT(B23,""\(([^)]*)\)""),"""")"),"OFFLINE MAY 22") -> OFFLINE MAY 22 | D23: =IFERROR(__xludf.DUMMYFUNCTION("TRIM(REGEXREPLACE(B23,""\s*\(.*?\)"",""""))"),"Bureau of Customs") -> Bureau of Customs
A24: L4-005-04DA8 | B24: Pres. Sergio Osmena, Sr. High School (DEFECTIVE AP) | C24: =IFERROR(__xludf.DUMMYFUNCTION("IFERROR(REGEXEXTRACT(B24,""\(([^)]*)\)""),"""")"),"DEFECTIVE AP") -> DEFECTIVE AP | D24: =IFERROR(__xludf.DUMMYFUNCTION("TRIM(REGEXREPLACE(B24,""\s*\(.*?\)"",""""))"),"Pres. Sergio Osmena, Sr. High School") -> Pres. Sergio Osmena, Sr. High School
A25: L4-005-0006D | B25: Intramuros Administration (OFFLINE MAY 12) | C25: =IFERROR(__xludf.DUMMYFUNCTION("IFERROR(REGEXEXTRACT(B25,""\(([^)]*)\)""),"""")"),"OFFLINE MAY 12") -> OFFLINE MAY 12 | D25: =IFERROR(__xludf.DUMMYFUNCTION("TRIM(REGEXREPLACE(B25,""\s*\(.*?\)"",""""))"),"Intramuros Administration") -> Intramuros Administration
C26: =IFERROR(__xludf.DUMMYFUNCTION("IFERROR(REGEXEXTRACT(B26,""\(([^)]*)\)""),"""")"),"") | D26: =IFERROR(__xludf.DUMMYFUNCTION("TRIM(REGEXREPLACE(B26,""\s*\(.*?\)"",""""))"),"")
A27: Muntinlupa City | C27: =IFERROR(__xludf.DUMMYFUNCTION("IFERROR(REGEXEXTRACT(B27,""\(([^)]*)\)""),"""")"),"") | D27: =IFERROR(__xludf.DUMMYFUNCTION("TRIM(REGEXREPLACE(B27,""\s*\(.*?\)"",""""))"),"")
A28: L4-00B-04CFF | B28: Muntinlupa National High School | C28: =IFERROR(__xludf.DUMMYFUNCTION("IFERROR(REGEXEXTRACT(B28,""\(([^)]*)\)""),"""")"),"") | D28: =IFERROR(__xludf.DUMMYFUNCTION("TRIM(REGEXREPLACE(B28,""\s*\(.*?\)"",""""))"),"Muntinlupa National High School") -> Muntinlupa National High School
A29: L4-00B-00686 | B29: Soldiers' Hills Elementary School | C29: =IFERROR(__xludf.DUMMYFUNCTION("IFERROR(REGEXEXTRACT(B29,""\(([^)]*)\)""),"""")"),"") | D29: =IFERROR(__xludf.DUMMYFUNCTION("TRIM(REGEXREPLACE(B29,""\s*\(.*?\)"",""""))"),"Soldiers' Hills Elementary School") -> Soldiers' Hills Elementary School
C30: =IFERROR(__xludf.DUMMYFUNCTION("IFERROR(REGEXEXTRACT(B30,""\(([^)]*)\)""),"""")"),"") | D30: =IFERROR(__xludf.DUMMYFUNCTION("TRIM(REGEXREPLACE(B30,""\s*\(.*?\)"",""""))"),"")
A31: Parañaque City | C31: =IFERROR(__xludf.DUMMYFUNCTION("IFERROR(REGEXEXTRACT(B31,""\(([^)]*)\)""),"""")"),"") | D31: =IFERROR(__xludf.DUMMYFUNCTION("TRIM(REGEXREPLACE(B31,""\s*\(.*?\)"",""""))"),"")
A32: L4-013-05ED0 | B32: Vitalez Health Center (SCHEDULE FOR SITE RELOCATION) | C32: =IFERROR(__xludf.DUMMYFUNCTION("IFERROR(REGEXEXTRACT(B32,""\(([^)]*)\)""),"""")"),"SCHEDULE FOR SITE RELOCATION") -> SCHEDULE FOR SITE RELOCATION | D32: =IFERROR(__xludf.DUMMYFUNCTION("TRIM(REGEXREPLACE(B32,""\s*\(.*?\)"",""""))"),"Vitalez Health Center") -> Vitalez Health Center
A33: L4-013-05EC1 | B33: Don Bosco Health Center | C33: =IFERROR(__xludf.DUMMYFUNCTION("IFERROR(REGEXEXTRACT(B33,""\(([^)]*)\)""),"""")"),"") | D33: =IFERROR(__xludf.DUMMYFUNCTION("TRIM(REGEXREPLACE(B33,""\s*\(.*?\)"",""""))"),"Don Bosco Health Center") -> Don Bosco Health Center
C34: =IFERROR(__xludf.DUMMYFUNCTION("IFERROR(REGEXEXTRACT(B34,""\(([^)]*)\)""),"""")"),"") | D34: =IFERROR(__xludf.DUMMYFUNCTION("TRIM(REGEXREPLACE(B34,""\s*\(.*?\)"",""""))"),"")
A35: Pasay City | C35: =IFERROR(__xludf.DUMMYFUNCTION("IFERROR(REGEXEXTRACT(B35,""\(([^)]*)\)""),"""")"),"") | D35: =IFERROR(__xludf.DUMMYFUNCTION("TRIM(REGEXREPLACE(B35,""\s*\(.*?\)"",""""))"),"")
A36: L4-008-06395 | B36: Philippine National Police Aviation Security Group (OFFLINE MAY 12) | C36: =IFERROR(__xludf.DUMMYFUNCTION("IFERROR(REGEXEXTRACT(B36,""\(([^)]*)\)""),"""")"),"OFFLINE MAY 12") -> OFFLINE MAY 12 | D36: =IFERROR(__xludf.DUMMYFUNCTION("TRIM(REGEXREPLACE(B36,""\s*\(.*?\)"",""""))"),"Philippine National Police Aviation Security Group") -> Philippine National Police Aviation Security Group
A37: L4-015-0004B | B37: Overseas Workers Welfare Administration | C37: =IFERROR(__xludf.DUMMYFUNCTION("IFERROR(REGEXEXTRACT(B37,""\(([^)]*)\)""),"""")"),"") | D37: =IFERROR(__xludf.DUMMYFUNCTION("TRIM(REGEXREPLACE(B37,""\s*\(.*?\)"",""""))"),"Overseas Workers Welfare Administration") -> Overseas Workers Welfare Administration

Sheet RAWDATA
A1: Caloocan City
A2: L4-003-063CE | B2: Barangay 14 Health Center | C2: (DEFECTIVE AP)
A3: L4-003-007B8 | B3: Bagong Barrio Elementary School
A4: L4-003-0017F | B4: Pres. Diosdado Macapagal Memorial Medical Center
A5: L4-003-05893 | B5: University of Caloocan City - Camarin Business Campus
A7: Makati City
A8: L4-008-00010 | B8: Board of Investments
A9: L4-008-006F2 | B9: Hen. Pio del Pilar Elementary School I
A10: L4-008-00701 | B10: Makati Elementary School
A12: Malabon City
A13: L4-007-049E0 | B13: Tañong Integrated School | C13: (DEFECTIVE AP)
A15: Manila City
A16: L4-005-05E5A | B16: M. Earnshaw Health Center
A17: L4-005-0007D | B17: Department of Finance | C17: (DEFECTIVE AP)
A18: L4-005-0008F | B18: Bureau of Customs
